Workbook

Sheet Start
B2: BESTANDS-MANAGER.COM
B3: Lagertransparenz
B4: Wo steckt Ihr Kapital? Bestandswert nach Warengruppe, Lagerort und ABC-Klasse – in 10 Minuten.
B8: SO GEHT'S · CA. 10 MINUTEN
B9: 1 | C9: Exportieren Sie aus Ihrer Warenwirtschaft eine Bestandsliste: Artikelnummer, Bezeichnung, Lagerort, Warengruppe, Bestand, Wert je Einheit, Mengeneinheit.
B10: 2 | C10: CSV-Datei in Excel über Daten → Aus Text/CSV öffnen (Trennzeichen Semikolon). Artikelnummer als Text, damit führende Nullen bleiben.
B11: 3 | C11: Im Blatt „Daten“ die Beispielzeilen in den orangen Spalten A–G löschen.
B12: 4 | C12: Ihre Werte ohne Überschrift kopieren, in „Daten“ auf A2 klicken: Rechtsklick → Einfügeoptionen → „Werte“.
B13: 5 | C13: Mehrere Lagerorte? Kein Problem: eine Zeile je Artikel und Lagerort. Die Datei zählt je Artikel zusammen.
B14: 6 | C14: Im Blatt „Ergebnis“ sehen Sie sofort, wo Ihr Kapital liegt.
C16: Ihre Daten bleiben auf Ihrem Rechner. Keine Makros, keine Internetverbindung. Die Beispieldaten sind erfunden und enthalten absichtlich 3 Datenfehler.
B18: EINSTELLUNGEN · ORANGE FELDER ANPASSEN
C19: Stichtag (Datum des Exports) | D19: 46326 | E19: Nur zur Dokumentation auf der Ergebnisseite.
C20: A-Artikel: bis Anteil am Bestandswert | D20: 0.8 | E20: Die wertvollsten Artikel, die zusammen bis zu diesem Anteil ausmachen.
C21: B-Artikel: bis Anteil am Bestandswert | D21: 0.95 | E21: Alles darüber sind C-Artikel.
B23: UND DANN?
C24: Diese Datei zeigt, WO das Kapital liegt – aber nicht, ob es zu viel ist. Dafür braucht es die Verkaufsdaten.
C25: Der Geld-im-Regal-Check (49 €) findet Ladenhüter, Überbestände und die 20 Artikel mit dem größten Hebel: bestands-manager.com
C26: Kostenlose Weitergabe erwünscht – bitte unverändert und mit Quellenangabe. © 2026 Bernd Schäfer, Bestands-Manager.com

Sheet Ergebnis
B2: BESTANDS-MANAGER.COM
B3: Ihr Ergebnis
B4: Wo Ihr Kapital im Lager liegt.
B7: Stichtag | C7: =Start!$D$19 -> 46326
B9: BESTANDSWERT GESAMT | C9: ARTIKEL MIT BESTAND | E9: A-ARTIKEL | H9: DATENQUALITÄT
B10: =SUM(Daten!$H$2:$H$5001) -> 142774.6 | C10: =SUMPRODUCT((Daten!$J$2:$J$5001=1)*(Daten!$I$2:$I$5001>0)) -> 27 | E10: =COUNTIFS(Daten!$N$2:$N$5001,"A",Daten!$J$2:$J$5001,1) -> 5 | H10: =IF(COUNTA(Daten!$A$2:$A$5001)>0,1-SUMPRODUCT((Daten!$A$2:$A$5001<>"")*(LEN(Daten!$O$2:$O$5001)>0))/COUNTA(Daten!$A$2:$A$5001),0) -> 0.91176471
B11: zu Ihren Bewertungspreisen | C11: je Artikel über alle Lager | E11: binden den Großteil des Kapitals | H11: Zeilen ohne Datenhinweis
B13: ="Die A-Artikel binden "&FIXED(SUMIF(Daten!$N$2:$N$5001,"A",Daten!$H$2:$H$5001),0)&" € – hier lohnt sich genaues Hinschauen am meisten." -> Die A-Artikel binden 113,485 € – hier lohnt sich genaues Hinschauen am meisten.
B15: BESTANDSWERT NACH WARENGRUPPE | G15: NACH LAGERORT
B16: Warengruppe | C16: Wert | D16: Anteil | E16: Artikel | G16: Lagerort | H16: Wert
B17: =IF(LARGE(Daten!$P$2:$P$5001,1)<=0,"",INDEX(Daten!$D$2:$D$5001,MATCH(LARGE(Daten!$P$2:$P$5001,1),Daten!$P$2:$P$5001,0))) -> Lager | C17: =IF(B17="","",SUMIF(Daten!$D$2:$D$5001,B17,Daten!$H$2:$H$5001)) -> 61592.4 | D17: =IF(B17="","",C17/MAX(1,SUM(Daten!$H$2:$H$5001))) -> 0.43139606 | E17: =IF(B17="","",COUNTIFS(Daten!$D$2:$D$5001,B17,Daten!$J$2:$J$5001,1)) -> 4 | G17: =IF(LARGE(Daten!$Q$2:$Q$5001,1)<=0,"",INDEX(Daten!$C$2:$C$5001,MATCH(LARGE(Daten!$Q$2:$Q$5001,1),Daten!$Q$2:$Q$5001,0))) -> Hauptlager | H17: =IF(G17="","",SUMIF(Daten!$C$2:$C$5001,G17,Daten!$H$2:$H$5001)) -> 121032.7
B18: =IF(LARGE(Daten!$P$2:$P$5001,2)<=0,"",INDEX(Daten!$D$2:$D$5001,MATCH(LARGE(Daten!$P$2:$P$5001,2),Daten!$P$2:$P$5001,0))) -> Antriebstechnik | C18: =IF(B18="","",SUMIF(Daten!$D$2:$D$5001,B18,Daten!$H$2:$H$5001)) -> 35396 | D18: =IF(B18="","",C18/MAX(1,SUM(Daten!$H$2:$H$5001))) -> 0.24791525 | E18: =IF(B18="","",COUNTIFS(Daten!$D$2:$D$5001,B18,Daten!$J$2:$J$5001,1)) -> 4 | G18: =IF(LARGE(Daten!$Q$2:$Q$5001,2)<=0,"",INDEX(Daten!$C$2:$C$5001,MATCH(LARGE(Daten!$Q$2:$Q$5001,2),Daten!$Q$2:$Q$5001,0))) -> Außenlager | H18: =IF(G18="","",SUMIF(Daten!$C$2:$C$5001,G18,Daten!$H$2:$H$5001)) -> 21741.9
B19: =IF(LARGE(Daten!$P$2:$P$5001,3)<=0,"",INDEX(Daten!$D$2:$D$5001,MATCH(LARGE(Daten!$P$2:$P$5001,3),Daten!$P$2:$P$5001,0))) -> Hydraulik | C19: =IF(B19="","",SUMIF(Daten!$D$2:$D$5001,B19,Daten!$H$2:$H$5001)) -> 28920 | D19: =IF(B19="","",C19/MAX(1,SUM(Daten!$H$2:$H$5001))) -> 0.20255704 | E19: =IF(B19="","",COUNTIFS(Daten!$D$2:$D$5001,B19,Daten!$J$2:$J$5001,1)) -> 5 | G19: =IF(LARGE(Daten!$Q$2:$Q$5001,3)<=0,"",INDEX(Daten!$C$2:$C$5001,MATCH(LARGE(Daten!$Q$2:$Q$5001,3),Daten!$Q$2:$Q$5001,0))) | H19: =IF(G19="","",SUMIF(Daten!$C$2:$C$5001,G19,Daten!$H$2:$H$5001))
B20: =IF(LARGE(Daten!$P$2:$P$5001,4)<=0,"",INDEX(Daten!$D$2:$D$5001,MATCH(LARGE(Daten!$P$2:$P$5001,4),Daten!$P$2:$P$5001,0))) -> Pumpen | C20: =IF(B20="","",SUMIF(Daten!$D$2:$D$5001,B20,Daten!$H$2:$H$5001)) -> 10890 | D20: =IF(B20="","",C20/MAX(1,SUM(Daten!$H$2:$H$5001))) -> 0.076274071 | E20: =IF(B20="","",COUNTIFS(Daten!$D$2:$D$5001,B20,Daten!$J$2:$J$5001,1)) -> 4 | G20: =IF(LARGE(Daten!$Q$2:$Q$5001,4)<=0,"",INDEX(Daten!$C$2:$C$5001,MATCH(LARGE(Daten!$Q$2:$Q$5001,4),Daten!$Q$2:$Q$5001,0))) | H20: =IF(G20="","",SUMIF(Daten!$C$2:$C$5001,G20,Daten!$H$2:$H$5001))
B21: =IF(LARGE(Daten!$P$2:$P$5001,5)<=0,"",INDEX(Daten!$D$2:$D$5001,MATCH(LARGE(Daten!$P$2:$P$5001,5),Daten!$P$2:$P$5001,0))) -> Dichtungen | C21: =IF(B21="","",SUMIF(Daten!$D$2:$D$5001,B21,Daten!$H$2:$H$5001)) -> 3082.6 | D21: =IF(B21="","",C21/MAX(1,SUM(Daten!$H$2:$H$5001))) -> 0.021590675 | E21: =IF(B21="","",COUNTIFS(Daten!$D$2:$D$5001,B21,Daten!$J$2:$J$5001,1)) -> 4 | G21: =IF(LARGE(Daten!$Q$2:$Q$5001,5)<=0,"",INDEX(Daten!$C$2:$C$5001,MATCH(LARGE(Daten!$Q$2:$Q$5001,5),Daten!$Q$2:$Q$5001,0))) | H21: =IF(G21="","",SUMIF(Daten!$C$2:$C$5001,G21,Daten!$H$2:$H$5001))
B22: =IF(LARGE(Daten!$P$2:$P$5001,6)<=0,"",INDEX(Daten!$D$2:$D$5001,MATCH(LARGE(Daten!$P$2:$P$5001,6),Daten!$P$2:$P$5001,0))) -> Schmierstoffe | C22: =IF(B22="","",SUMIF(Daten!$D$2:$D$5001,B22,Daten!$H$2:$H$5001)) -> 1911.2 | D22: =IF(B22="","",C22/MAX(1,SUM(Daten!$H$2:$H$5001))) -> 0.013386135 | E22: =IF(B22="","",COUNTIFS(Daten!$D$2:$D$5001,B22,Daten!$J$2:$J$5001,1)) -> 3 | G22: =IF(LARGE(Daten!$Q$2:$Q$5001,6)<=0,"",INDEX(Daten!$C$2:$C$5001,MATCH(LARGE(Daten!$Q$2:$Q$5001,6),Daten!$Q$2:$Q$5001,0))) | H22: =IF(G22="","",SUMIF(Daten!$C$2:$C$5001,G22,Daten!$H$2:$H$5001))
B23: =IF(LARGE(Daten!$P$2:$P$5001,7)<=0,"",INDEX(Daten!$D$2:$D$5001,MATCH(LARGE(Daten!$P$2:$P$5001,7),Daten!$P$2:$P$5001,0))) -> Pneumatik | C23: =IF(B23="","",SUMIF(Daten!$D$2:$D$5001,B23,Daten!$H$2:$H$5001)) -> 968.8 | D23: =IF(B23="","",C23/MAX(1,SUM(Daten!$H$2:$H$5001))) -> 0.0067855207 | E23: =IF(B23="","",COUNTIFS(Daten!$D$2:$D$5001,B23,Daten!$J$2:$J$5001,1)) -> 4
B24: =IF(LARGE(Daten!$P$2:$P$5001,8)<=0,"",INDEX(Daten!$D$2:$D$5001,MATCH(LARGE(Daten!$P$2:$P$5001,8),Daten!$P$2:$P$5001,0))) | C24: =IF(B24="","",SUMIF(Daten!$D$2:$D$5001,B24,Daten!$H$2:$H$5001)) | D24: =IF(B24="","",C24/MAX(1,SUM(Daten!$H$2:$H$5001))) | E24: =IF(B24="","",COUNTIFS(Daten!$D$2:$D$5001,B24,Daten!$J$2:$J$5001,1)) | G24: ABC-VERTEILUNG
B25: =IF(LARGE(Daten!$P$2:$P$5001,9)<=0,"",INDEX(Daten!$D$2:$D$5001,MATCH(LARGE(Daten!$P$2:$P$5001,9),Daten!$P$2:$P$5001,0))) | C25: =IF(B25="","",SUMIF(Daten!$D$2:$D$5001,B25,Daten!$H$2:$H$5001)) | D25: =IF(B25="","",C25/MAX(1,SUM(Daten!$H$2:$H$5001))) | E25: =IF(B25="","",COUNTIFS(Daten!$D$2:$D$5001,B25,Daten!$J$2:$J$5001,1)) | G25: Klasse | H25: Wert
B26: =IF(LARGE(Daten!$P$2:$P$5001,10)<=0,"",INDEX(Daten!$D$2:$D$5001,MATCH(LARGE(Daten!$P$2:$P$5001,10),Daten!$P$2:$P$5001,0))) | C26: =IF(B26="","",SUMIF(Daten!$D$2:$D$5001,B26,Daten!$H$2:$H$5001)) | D26: =IF(B26="","",C26/MAX(1,SUM(Daten!$H$2:$H$5001))) | E26: =IF(B26="","",COUNTIFS(Daten!$D$2:$D$5001,B26,Daten!$J$2:$J$5001,1)) | G26: A | H26: =SUMIF(Daten!$N$2:$N$5001,G26,Daten!$H$2:$H$5001) -> 113485
B27: =IF(LARGE(Daten!$P$2:$P$5001,11)<=0,"",INDEX(Daten!$D$2:$D$5001,MATCH(LARGE(Daten!$P$2:$P$5001,11),Daten!$P$2:$P$5001,0))) | C27: =IF(B27="","",SUMIF(Daten!$D$2:$D$5001,B27,Daten!$H$2:$H$5001)) | D27: =IF(B27="","",C27/MAX(1,SUM(Daten!$H$2:$H$5001))) | E27: =IF(B27="","",COUNTIFS(Daten!$D$2:$D$5001,B27,Daten!$J$2:$J$5001,1)) | G27: B | H27: =SUMIF(Daten!$N$2:$N$5001,G27,Daten!$H$2:$H$5001) -> 20355
B28: =IF(LARGE(Daten!$P$2:$P$5001,12)<=0,"",INDEX(Daten!$D$2:$D$5001,MATCH(LARGE(Daten!$P$2:$P$5001,12),Daten!$P$2:$P$5001,0))) | C28: =IF(B28="","",SUMIF(Daten!$D$2:$D$5001,B28,Daten!$H$2:$H$5001)) | D28: =IF(B28="","",C28/MAX(1,SUM(Daten!$H$2:$H$5001))) | E28: =IF(B28="","",COUNTIFS(Daten!$D$2:$D$5001,B28,Daten!$J$2:$J$5001,1)) | G28: C | H28: =SUMIF(Daten!$N$2:$N$5001,G28,Daten!$H$2:$H$5001) -> 8934.6
G29: ="A: "&COUNTIFS(Daten!$N$2:$N$5001,"A",Daten!$J$2:$J$5001,1)&" · B: "&COUNTIFS(Daten!$N$2:$N$5001,"B",Daten!$J$2:$J$5001,1)&" · C: "&COUNTIFS(Daten!$N$2:$N$5001,"C",Daten!$J$2:$J$5001,1)&" Artikel" -> A: 5 · B: 5 · C: 17 Artikel
B30: DIE 15 ARTIKEL MIT DEM HÖCHSTEN BESTANDSWERT
B31: Artikelnummer | C31: Bezeichnung | D31: Warengruppe | E31: Wert | G31: ABC
B32: =IF(LARGE(Daten!$K$2:$K$5001,1)<=0,"",INDEX(Daten!$A$2:$A$5001,MATCH(LARGE(Daten!$K$2:$K$5001,1),Daten!$K$2:$K$5001,0))) -> 0001016 | C32: =IF(LARGE(Daten!$K$2:$K$5001,1)<=0,"",INDEX(Daten!$B$2:$B$5001,MATCH(LARGE(Daten!$K$2:$K$5001,1),Daten!$K$2:$K$5001,0))) -> Stehlagereinheit | D32: =IF(LARGE(Daten!$K$2:$K$5001,1)<=0,"",INDEX(Daten!$D$2:$D$5001,MATCH(LARGE(Daten!$K$2:$K$5001,1),Daten!$K$2:$K$5001,0))) -> Lager | E32: =IF(LARGE(Daten!$K$2:$K$5001,1)<=0,"",INDEX(Daten!$I$2:$I$5001,MATCH(LARGE(Daten!$K$2:$K$5001,1),Daten!$K$2:$K$5001,0))) -> 60800 | G32: =IF(LARGE(Daten!$K$2:$K$5001,1)<=0,"",INDEX(Daten!$N$2:$N$5001,MATCH(LARGE(Daten!$K$2:$K$5001,1),Daten!$K$2:$K$5001,0))) -> A
B33: =IF(LARGE(Daten!$K$2:$K$5001,2)<=0,"",INDEX(Daten!$A$2:$A$5001,MATCH(LARGE(Daten!$K$2:$K$5001,2),Daten!$K$2:$K$5001,0))) -> 0001019 | C33: =IF(LARGE(Daten!$K$2:$K$5001,2)<=0,"",INDEX(Daten!$B$2:$B$5001,MATCH(LARGE(Daten!$K$2:$K$5001,2),Daten!$K$2:$K$5001,0))) -> Zahnriemen | D33: =IF(LARGE(Daten!$K$2:$K$5001,2)<=0,"",INDEX(Daten!$D$2:$D$5001,MATCH(LARGE(Daten!$K$2:$K$5001,2),Daten!$K$2:$K$5001,0))) -> Antriebstechnik | E33: =IF(LARGE(Daten!$K$2:$K$5001,2)<=0,"",INDEX(Daten!$I$2:$I$5001,MATCH(LARGE(Daten!$K$2:$K$5001,2),Daten!$K$2:$K$5001,0))) -> 21600 | G33: =IF(LARGE(Daten!$K$2:$K$5001,2)<=0,"",INDEX(Daten!$N$2:$N$5001,MATCH(LARGE(Daten!$K$2:$K$5001,2),Daten!$K$2:$K$5001,0))) -> A
B34: =IF(LARGE(Daten!$K$2:$K$5001,3)<=0,"",INDEX(Daten!$A$2:$A$5001,MATCH(LARGE(Daten!$K$2:$K$5001,3),Daten!$K$2:$K$5001,0))) -> 0001001 | C34: =IF(LARGE(Daten!$K$2:$K$5001,3)<=0,"",INDEX(Daten!$B$2:$B$5001,MATCH(LARGE(Daten!$K$2:$K$5001,3),Daten!$K$2:$K$5001,0))) -> Hydraulikventil | D34: =IF(LARGE(Daten!$K$2:$K$5001,3)<=0,"",INDEX(Daten!$D$2:$D$5001,MATCH(LARGE(Daten!$K$2:$K$5001,3),Daten!$K$2:$K$5001,0))) -> Hydraulik | E34: =IF(LARGE(Daten!$K$2:$K$5001,3)<=0,"",INDEX(Daten!$I$2:$I$5001,MATCH(LARGE(Daten!$K$2:$K$5001,3),Daten!$K$2:$K$5001,0))) -> 12125 | G34: =IF(LARGE(Daten!$K$2:$K$5001,3)<=0,"",INDEX(Daten!$N$2:$N$5001,MATCH(LARGE(Daten!$K$2:$K$5001,3),Daten!$K$2:$K$5001,0))) -> A
B35: =IF(LARGE(Daten!$K$2:$K$5001,4)<=0,"",INDEX(Daten!$A$2:$A$5001,MATCH(LARGE(Daten!$K$2:$K$5001,4),Daten!$K$2:$K$5001,0))) -> 0001018 | C35: =IF(LARGE(Daten!$K$2:$K$5001,4)<=0,"",INDEX(Daten!$B$2:$B$5001,MATCH(LARGE(Daten!$K$2:$K$5001,4),Daten!$K$2:$K$5001,0))) -> Keilriemen SPZ | D35: =IF(LARGE(Daten!$K$2:$K$5001,4)<=0,"",INDEX(Daten!$D$2:$D$5001,MATCH(LARGE(Daten!$K$2:$K$5001,4),Daten!$K$2:$K$5001,0))) -> Antriebstechnik | E35: =IF(LARGE(Daten!$K$2:$K$5001,4)<=0,"",INDEX(Daten!$I$2:$I$5001,MATCH(LARGE(Daten!$K$2:$K$5001,4),Daten!$K$2:$K$5001,0))) -> 11520 | G35: =IF(LARGE(Daten!$K$2:$K$5001,4)<=0,"",INDEX(Daten!$N$2:$N$5001,MATCH(LARGE(Daten!$K$2:$K$5001,4),Daten!$K$2:$K$5001,0))) -> A
B36: =IF(LARGE(Daten!$K$2:$K$5001,5)<=0,"",INDEX(Daten!$A$2:$A$5001,MATCH(LARGE(Daten!$K$2:$K$5001,5),Daten!$K$2:$K$5001,0))) -> 0001003 | C36: =IF(LARGE(Daten!$K$2:$K$5001,5)<=0,"",INDEX(Daten!$B$2:$B$5001,MATCH(LARGE(Daten!$K$2:$K$5001,5),Daten!$K$2:$K$5001,0))) -> Druckspeicher | D36: =IF(LARGE(Daten!$K$2:$K$5001,5)<=0,"",INDEX(Daten!$D$2:$D$5001,MATCH(LARGE(Daten!$K$2:$K$5001,5),Daten!$K$2:$K$5001,0))) -> Hydraulik | E36: =IF(LARGE(Daten!$K$2:$K$5001,5)<=0,"",INDEX(Daten!$I$2:$I$5001,MATCH(LARGE(Daten!$K$2:$K$5001,5),Daten!$K$2:$K$5001,0))) -> 7440 | G36: =IF(LARGE(Daten!$K$2:$K$5001,5)<=0,"",INDEX(Daten!$N$2:$N$5001,MATCH(LARGE(Daten!$K$2:$K$5001,5),Daten!$K$2:$K$5001,0))) -> A
B37: =IF(LARGE(Daten!$K$2:$K$5001,6)<=0,"",INDEX(Daten!$A$2:$A$5001,MATCH(LARGE(Daten!$K$2:$K$5001,6),Daten!$K$2:$K$5001,0))) -> 0001011 | C37: =IF(LARGE(Daten!$K$2:$K$5001,6)<=0,"",INDEX(Daten!$B$2:$B$5001,MATCH(LARGE(Daten!$K$2:$K$5001,6),Daten!$K$2:$K$5001,0))) -> Tauchpumpe | D37: =IF(LARGE(Daten!$K$2:$K$5001,6)<=0,"",INDEX(Daten!$D$2:$D$5001,MATCH(LARGE(Daten!$K$2:$K$5001,6),Daten!$K$2:$K$5001,0))) -> Pumpen | E37: =IF(LARGE(Daten!$K$2:$K$5001,6)<=0,"",INDEX(Daten!$I$2:$I$5001,MATCH(LARGE(Daten!$K$2:$K$5001,6),Daten!$K$2:$K$5001,0))) -> 6300 | G37: =IF(LARGE(Daten!$K$2:$K$5001,6)<=0,"",INDEX(Daten!$N$2:$N$5001,MATCH(LARGE(Daten!$K$2:$K$5001,6),Daten!$K$2:$K$5001,0))) -> B
B38: =IF(LARGE(Daten!$K$2:$K$5001,7)<=0,"",INDEX(Daten!$A$2:$A$5001,MATCH(LARGE(Daten!$K$2:$K$5001,7),Daten!$K$2:$K$5001,0))) -> 0001002 | C38: =IF(LARGE(Daten!$K$2:$K$5001,7)<=0,"",INDEX(Daten!$B$2:$B$5001,MATCH(LARGE(Daten!$K$2:$K$5001,7),Daten!$K$2:$K$5001,0))) -> Hydraulikschlauch 1 m | D38: =IF(LARGE(Daten!$K$2:$K$5001,7)<=0,"",INDEX(Daten!$D$2:$D$5001,MATCH(LARGE(Daten!$K$2:$K$5001,7),Daten!$K$2:$K$5001,0))) -> Hydraulik | E38: =IF(LARGE(Daten!$K$2:$K$5001,7)<=0,"",INDEX(Daten!$I$2:$I$5001,MATCH(LARGE(Daten!$K$2:$K$5001,7),Daten!$K$2:$K$5001,0))) -> 4975 | G38: =IF(LARGE(Daten!$K$2:$K$5001,7)<=0,"",INDEX(Daten!$N$2:$N$5001,MATCH(LARGE(Daten!$K$2:$K$5001,7),Daten!$K$2:$K$5001,0))) -> B
B39: =IF(LARGE(Daten!$K$2:$K$5001,8)<=0,"",INDEX(Daten!$A$2:$A$5001,MATCH(LARGE(Daten!$K$2:$K$5001,8),Daten!$K$2:$K$5001,0))) -> 0001012 | C39: =IF(LARGE(Daten!$K$2:$K$5001,8)<=0,"",INDEX(Daten!$B$2:$B$5001,MATCH(LARGE(Daten!$K$2:$K$5001,8),Daten!$K$2:$K$5001,0))) -> Pumpenlaufrad | D39: =IF(LARGE(Daten!$K$2:$K$5001,8)<=0,"",INDEX(Daten!$D$2:$D$5001,MATCH(LARGE(Daten!$K$2:$K$5001,8),Daten!$K$2:$K$5001,0))) -> Pumpen | E39: =IF(LARGE(Daten!$K$2:$K$5001,8)<=0,"",INDEX(Daten!$I$2:$I$5001,MATCH(LARGE(Daten!$K$2:$K$5001,8),Daten!$K$2:$K$5001,0))) -> 3700 | G39: =IF(LARGE(Daten!$K$2:$K$5001,8)<=0,"",INDEX(Daten!$N$2:$N$5001,MATCH(LARGE(Daten!$K$2:$K$5001,8),Daten!$K$2:$K$5001,0))) -> B
B40: =IF(LARGE(Daten!$K$2:$K$5001,9)<=0,"",INDEX(Daten!$A$2:$A$5001,MATCH(LARGE(Daten!$K$2:$K$5001,9),Daten!$K$2:$K$5001,0))) -> 0001005 | C40: =IF(LARGE(Daten!$K$2:$K$5001,9)<=0,"",INDEX(Daten!$B$2:$B$5001,MATCH(LARGE(Daten!$K$2:$K$5001,9),Daten!$K$2:$K$5001,0))) -> Kupplung DN10 | D40: =IF(LARGE(Daten!$K$2:$K$5001,9)<=0,"",INDEX(Daten!$D$2:$D$5001,MATCH(LARGE(Daten!$K$2:$K$5001,9),Daten!$K$2:$K$5001,0))) -> Hydraulik | E40: =IF(LARGE(Daten!$K$2:$K$5001,9)<=0,"",INDEX(Daten!$I$2:$I$5001,MATCH(LARGE(Daten!$K$2:$K$5001,9),Daten!$K$2:$K$5001,0))) -> 3100 | G40: =IF(LARGE(Daten!$K$2:$K$5001,9)<=0,"",INDEX(Daten!$N$2:$N$5001,MATCH(LARGE(Daten!$K$2:$K$5001,9),Daten!$K$2:$K$5001,0))) -> B
B41: =IF(LARGE(Daten!$K$2:$K$5001,10)<=0,"",INDEX(Daten!$A$2:$A$5001,MATCH(LARGE(Daten!$K$2:$K$5001,10),Daten!$K$2:$K$5001,0))) -> 0001008 | C41: =IF(LARGE(Daten!$K$2:$K$5001,10)<=0,"",INDEX(Daten!$B$2:$B$5001,MATCH(LARGE(Daten!$K$2:$K$5001,10),Daten!$K$2:$K$5001,0))) -> Wellendichtring | D41: =IF(LARGE(Daten!$K$2:$K$5001,10)<=0,"",INDEX(Daten!$D$2:$D$5001,MATCH(LARGE(Daten!$K$2:$K$5001,10),Daten!$K$2:$K$5001,0))) -> Dichtungen | E41: =IF(LARGE(Daten!$K$2:$K$5001,10)<=0,"",INDEX(Daten!$I$2:$I$5001,MATCH(LARGE(Daten!$K$2:$K$5001,10),Daten!$K$2:$K$5001,0))) -> 2280 | G41: =IF(LARGE(Daten!$K$2:$K$5001,10)<=0,"",INDEX(Daten!$N$2:$N$5001,MATCH(LARGE(Daten!$K$2:$K$5001,10),Daten!$K$2:$K$5001,0))) -> B
B42: =IF(LARGE(Daten!$K$2:$K$5001,11)<=0,"",INDEX(Daten!$A$2:$A$5001,MATCH(LARGE(Daten!$K$2:$K$5001,11),Daten!$K$2:$K$5001,0))) -> 0001020 | C42: =IF(LARGE(Daten!$K$2:$K$5001,11)<=0,"",INDEX(Daten!$B$2:$B$5001,MATCH(LARGE(Daten!$K$2:$K$5001,11),Daten!$K$2:$K$5001,0))) -> Getriebemotor 0,75 kW | D42: =IF(LARGE(Daten!$K$2:$K$5001,11)<=0,"",INDEX(Daten!$D$2:$D$5001,MATCH(LARGE(Daten!$K$2:$K$5001,11),Daten!$K$2:$K$5001,0))) -> Antriebstechnik | E42: =IF(LARGE(Daten!$K$2:$K$5001,11)<=0,"",INDEX(Daten!$I$2:$I$5001,MATCH(LARGE(Daten!$K$2:$K$5001,11),Daten!$K$2:$K$5001,0))) -> 2240 | G42: =IF(LARGE(Daten!$K$2:$K$5001,11)<=0,"",INDEX(Daten!$N$2:$N$5001,MATCH(LARGE(Daten!$K$2:$K$5001,11),Daten!$K$2:$K$5001,0))) -> C
B43: =IF(LARGE(Daten!$K$2:$K$5001,12)<=0,"",INDEX(Daten!$A$2:$A$5001,MATCH(LARGE(Daten!$K$2:$K$5001,12),Daten!$K$2:$K$5001,0))) -> 0001023 | C43: =IF(LARGE(Daten!$K$2:$K$5001,12)<=0,"",INDEX(Daten!$B$2:$B$5001,MATCH(LARGE(Daten!$K$2:$K$5001,12),Daten!$K$2:$K$5001,0))) -> Getriebeöl 20 l | D43: =IF(LARGE(Daten!$K$2:$K$5001,12)<=0,"",INDEX(Daten!$D$2:$D$5001,MATCH(LARGE(Daten!$K$2:$K$5001,12),Daten!$K$2:$K$5001,0))) -> Schmierstoffe | E43: =IF(LARGE(Daten!$K$2:$K$5001,12)<=0,"",INDEX(Daten!$I$2:$I$5001,MATCH(LARGE(Daten!$K$2:$K$5001,12),Daten!$K$2:$K$5001,0))) -> 1380 | G43: =IF(LARGE(Daten!$K$2:$K$5001,12)<=0,"",INDEX(Daten!$N$2:$N$5001,MATCH(LARGE(Daten!$K$2:$K$5001,12),Daten!$K$2:$K$5001,0))) -> C
B44: =IF(LARGE(Daten!$K$2:$K$5001,13)<=0,"",INDEX(Daten!$A$2:$A$5001,MATCH(LARGE(Daten!$K$2:$K$5001,13),Daten!$K$2:$K$5001,0))) -> 0001004 | C44: =IF(LARGE(Daten!$K$2:$K$5001,13)<=0,"",INDEX(Daten!$B$2:$B$5001,MATCH(LARGE(Daten!$K$2:$K$5001,13),Daten!$K$2:$K$5001,0))) -> Hydraulikzylinder | D44: =IF(LARGE(Daten!$K$2:$K$5001,13)<=0,"",INDEX(Daten!$D$2:$D$5001,MATCH(LARGE(Daten!$K$2:$K$5001,13),Daten!$K$2:$K$5001,0))) -> Hydraulik | E44: =IF(LARGE(Daten!$K$2:$K$5001,13)<=0,"",INDEX(Daten!$I$2:$I$5001,MATCH(LARGE(Daten!$K$2:$K$5001,13),Daten!$K$2:$K$5001,0))) -> 1280 | G44: =IF(LARGE(Daten!$K$2:$K$5001,13)<=0,"",INDEX(Daten!$N$2:$N$5001,MATCH(LARGE(Daten!$K$2:$K$5001,13),Daten!$K$2:$K$5001,0))) -> C
B45: =IF(LARGE(Daten!$K$2:$K$5001,14)<=0,"",INDEX(Daten!$A$2:$A$5001,MATCH(LARGE(Daten!$K$2:$K$5001,14),Daten!$K$2:$K$5001,0))) -> 0001013 | C45: =IF(LARGE(Daten!$K$2:$K$5001,14)<=0,"",INDEX(Daten!$B$2:$B$5001,MATCH(LARGE(Daten!$K$2:$K$5001,14),Daten!$K$2:$K$5001,0))) -> Dosierpumpe | D45: =IF(LARGE(Daten!$K$2:$K$5001,14)<=0,"",INDEX(Daten!$D$2:$D$5001,MATCH(LARGE(Daten!$K$2:$K$5001,14),Daten!$K$2:$K$5001,0))) -> Pumpen | E45: =IF(LARGE(Daten!$K$2:$K$5001,14)<=0,"",INDEX(Daten!$I$2:$I$5001,MATCH(LARGE(Daten!$K$2:$K$5001,14),Daten!$K$2:$K$5001,0))) -> 890 | G45: =IF(LARGE(Daten!$K$2:$K$5001,14)<=0,"",INDEX(Daten!$N$2:$N$5001,MATCH(LARGE(Daten!$K$2:$K$5001,14),Daten!$K$2:$K$5001,0))) -> C
B46: =IF(LARGE(Daten!$K$2:$K$5001,15)<=0,"",INDEX(Daten!$A$2:$A$5001,MATCH(LARGE(Daten!$K$2:$K$5001,15),Daten!$K$2:$K$5001,0))) -> 0001007 | C46: =IF(LARGE(Daten!$K$2:$K$5001,15)<=0,"",INDEX(Daten!$B$2:$B$5001,MATCH(LARGE(Daten!$K$2:$K$5001,15),Daten!$K$2:$K$5001,0))) -> O-Ring-Sortiment | D46: =IF(LARGE(Daten!$K$2:$K$5001,15)<=0,"",INDEX(Daten!$D$2:$D$5001,MATCH(LARGE(Daten!$K$2:$K$5001,15),Daten!$K$2:$K$5001,0))) -> Dichtungen | E46: =IF(LARGE(Daten!$K$2:$K$5001,15)<=0,"",INDEX(Daten!$I$2:$I$5001,MATCH(LARGE(Daten!$K$2:$K$5001,15),Daten!$K$2:$K$5001,0))) -> 789.7 | G46: =IF(LARGE(Daten!$K$2:$K$5001,15)<=0,"",INDEX(Daten!$N$2:$N$5001,MATCH(LARGE(Daten!$K$2:$K$5001,15),Daten!$K$2:$K$5001,0))) -> C
...

Sheet Daten
A1: Artikelnummer | B1: Bezeichnung | C1: Lagerstandort | D1: Warengruppe | E1: Bestand (ME) | F1: Wert je ME (EUR) | G1: Mengeneinheit | H1: Bestandswert (€) | I1: Artikelwert alle Lager (€) | J1: erstes Vorkommen | K1: Sortierhilfe Artikel | L1: kum. Anteil | M1: Anteil Artikel | N1: ABC | O1: Datenhinweis | P1: Sortierhilfe WG | Q1: Sortierhilfe Lager
A2: 0001001 | B2: Hydraulikventil | C2: Hauptlager | D2: Hydraulik | E2: 250 | F2: 48.5 | G2: Stk | H2: =IF($A2="","",IF(OR(NOT(ISNUMBER(E2)),NOT(ISNUMBER(F2))),"",MAX(0,E2)*F2)) -> 12125 | I2: =IF($A2="","",SUMIF($A$2:$A$5001,$A2,$H$2:$H$5001)) -> 12125 | J2: =IF($A2="",0,IF(COUNTIF($A$2:A2,$A2)=1,1,0)) -> 1 | K2: =IF(J2=1,N(I2)+ROW()/10000000,0) -> 12125 | L2: =IF(AND(J2=1,N(I2)>0),SUMIF($K$2:$K$5001,">="&K2,$I$2:$I$5001)/MAX(1,SUM($H$2:$H$5001)),"") -> 0.66205754 | M2: =IF($A2="","",INDEX($L$2:$L$5001,MATCH($A2,$A$2:$A$5001,0))) -> 0.66205754 | N2: =IF($A2="","",IF(N(M2)=0,"–",IF(M2<=Start!$D$20,"A",IF(M2<=Start!$D$21,"B","C")))) -> A | O2: =IF($A2="","",IF(NOT(ISNUMBER(F2)),"Wert fehlt; ",IF(F2<=0,"Wert ist 0; ",""))&IF(NOT(ISNUMBER(E2)),"Bestand fehlt; ",IF(E2<0,"Bestand negativ; ",IF(E2=0,"Nullbestand; ","")))&IF(D2="","Warengruppe fehlt; ","")&IF(B2="","Bezeichnung fehlt; ","")&IF(COUNTIFS($A$2:$A$5001,$A2,$C$2:$C$5001,C2)>1,"Artikel doppelt im selben Lager; ","")) | P2: =IF(OR($A2="",D2=""),0,IF(COUNTIF($D$2:D2,D2)=1,SUMIF($D$2:$D$5001,D2,$H$2:$H$5001)+ROW()/10000000,0)) -> 28920 | Q2: =IF(OR($A2="",C2=""),0,IF(COUNTIF($C$2:C2,C2)=1,SUMIF($C$2:$C$5001,C2,$H$2:$H$5001)+ROW()/10000000,0)) -> 121032.7
A3: 0001002 | B3: Hydraulikschlauch 1 m | C3: Hauptlager | D3: Hydraulik | E3: 250 | F3: 19.9 | G3: Stk | H3: =IF($A3="","",IF(OR(NOT(ISNUMBER(E3)),NOT(ISNUMBER(F3))),"",MAX(0,E3)*F3)) -> 4975 | I3: =IF($A3="","",SUMIF($A$2:$A$5001,$A3,$H$2:$H$5001)) -> 4975 | J3: =IF($A3="",0,IF(COUNTIF($A$2:A3,$A3)=1,1,0)) -> 1 | K3: =IF(J3=1,N(I3)+ROW()/10000000,0) -> 4975 | L3: =IF(AND(J3=1,N(I3)>0),SUMIF($K$2:$K$5001,">="&K3,$I$2:$I$5001)/MAX(1,SUM($H$2:$H$5001)),"") -> 0.8738249 | M3: =IF($A3="","",INDEX($L$2:$L$5001,MATCH($A3,$A$2:$A$5001,0))) -> 0.8738249 | N3: =IF($A3="","",IF(N(M3)=0,"–",IF(M3<=Start!$D$20,"A",IF(M3<=Start!$D$21,"B","C")))) -> B | O3: =IF($A3="","",IF(NOT(ISNUMBER(F3)),"Wert fehlt; ",IF(F3<=0,"Wert ist 0; ",""))&IF(NOT(ISNUMBER(E3)),"Bestand fehlt; ",IF(E3<0,"Bestand negativ; ",IF(E3=0,"Nullbestand; ","")))&IF(D3="","Warengruppe fehlt; ","")&IF(B3="","Bezeichnung fehlt; ","")&IF(COUNTIFS($A$2:$A$5001,$A3,$C$2:$C$5001,C3)>1,"Artikel doppelt im selben Lager; ","")) | P3: =IF(OR($A3="",D3=""),0,IF(COUNTIF($D$2:D3,D3)=1,SUMIF($D$2:$D$5001,D3,$H$2:$H$5001)+ROW()/10000000,0)) -> 0 | Q3: =IF(OR($A3="",C3=""),0,IF(COUNTIF($C$2:C3,C3)=1,SUMIF($C$2:$C$5001,C3,$H$2:$H$5001)+ROW()/10000000,0)) -> 0
A4: 0001003 | B4: Druckspeicher | C4: Hauptlager | D4: Hydraulik | E4: 24 | F4: 310 | G4: Stk | H4: =IF($A4="","",IF(OR(NOT(ISNUMBER(E4)),NOT(ISNUMBER(F4))),"",MAX(0,E4)*F4)) -> 7440 | I4: =IF($A4="","",SUMIF($A$2:$A$5001,$A4,$H$2:$H$5001)) -> 7440 | J4: =IF($A4="",0,IF(COUNTIF($A$2:A4,$A4)=1,1,0)) -> 1 | K4: =IF(J4=1,N(I4)+ROW()/10000000,0) -> 7440 | L4: =IF(AND(J4=1,N(I4)>0),SUMIF($K$2:$K$5001,">="&K4,$I$2:$I$5001)/MAX(1,SUM($H$2:$H$5001)),"") -> 0.79485427 | M4: =IF($A4="","",INDEX($L$2:$L$5001,MATCH($A4,$A$2:$A$5001,0))) -> 0.79485427 | N4: =IF($A4="","",IF(N(M4)=0,"–",IF(M4<=Start!$D$20,"A",IF(M4<=Start!$D$21,"B","C")))) -> A | O4: =IF($A4="","",IF(NOT(ISNUMBER(F4)),"Wert fehlt; ",IF(F4<=0,"Wert ist 0; ",""))&IF(NOT(ISNUMBER(E4)),"Bestand fehlt; ",IF(E4<0,"Bestand negativ; ",IF(E4=0,"Nullbestand; ","")))&IF(D4="","Warengruppe fehlt; ","")&IF(B4="","Bezeichnung fehlt; ","")&IF(COUNTIFS($A$2:$A$5001,$A4,$C$2:$C$5001,C4)>1,"Artikel doppelt im selben Lager; ","")) | P4: =IF(OR($A4="",D4=""),0,IF(COUNTIF($D$2:D4,D4)=1,SUMIF($D$2:$D$5001,D4,$H$2:$H$5001)+ROW()/10000000,0)) -> 0 | Q4: =IF(OR($A4="",C4=""),0,IF(COUNTIF($C$2:C4,C4)=1,SUMIF($C$2:$C$5001,C4,$H$2:$H$5001)+ROW()/10000000,0)) -> 0
A5: 0001004 | B5: Hydraulikzylinder | C5: Hauptlager | D5: Hydraulik | E5: 2 | F5: 640 | G5: Stk | H5: =IF($A5="","",IF(OR(NOT(ISNUMBER(E5)),NOT(ISNUMBER(F5))),"",MAX(0,E5)*F5)) -> 1280 | I5: =IF($A5="","",SUMIF($A$2:$A$5001,$A5,$H$2:$H$5001)) -> 1280 | J5: =IF($A5="",0,IF(COUNTIF($A$2:A5,$A5)=1,1,0)) -> 1 | K5: =IF(J5=1,N(I5)+ROW()/10000000,0) -> 1280 | L5: =IF(AND(J5=1,N(I5)>0),SUMIF($K$2:$K$5001,">="&K5,$I$2:$I$5001)/MAX(1,SUM($H$2:$H$5001)),"") -> 0.97174147 | M5: =IF($A5="","",INDEX($L$2:$L$5001,MATCH($A5,$A$2:$A$5001,0))) -> 0.97174147 | N5: =IF($A5="","",IF(N(M5)=0,"–",IF(M5<=Start!$D$20,"A",IF(M5<=Start!$D$21,"B","C")))) -> C | O5: =IF($A5="","",IF(NOT(ISNUMBER(F5)),"Wert fehlt; ",IF(F5<=0,"Wert ist 0; ",""))&IF(NOT(ISNUMBER(E5)),"Bestand fehlt; ",IF(E5<0,"Bestand negativ; ",IF(E5=0,"Nullbestand; ","")))&IF(D5="","Warengruppe fehlt; ","")&IF(B5="","Bezeichnung fehlt; ","")&IF(COUNTIFS($A$2:$A$5001,$A5,$C$2:$C$5001,C5)>1,"Artikel doppelt im selben Lager; ","")) | P5: =IF(OR($A5="",D5=""),0,IF(COUNTIF($D$2:D5,D5)=1,SUMIF($D$2:$D$5001,D5,$H$2:$H$5001)+ROW()/10000000,0)) -> 0 | Q5: =IF(OR($A5="",C5=""),0,IF(COUNTIF($C$2:C5,C5)=1,SUMIF($C$2:$C$5001,C5,$H$2:$H$5001)+ROW()/10000000,0)) -> 0
A6: 0001005 | B6: Kupplung DN10 | C6: Hauptlager | D6: Hydraulik | E6: 250 | F6: 12.4 | G6: Stk | H6: =IF($A6="","",IF(OR(NOT(ISNUMBER(E6)),NOT(ISNUMBER(F6))),"",MAX(0,E6)*F6)) -> 3100 | I6: =IF($A6="","",SUMIF($A$2:$A$5001,$A6,$H$2:$H$5001)) -> 3100 | J6: =IF($A6="",0,IF(COUNTIF($A$2:A6,$A6)=1,1,0)) -> 1 | K6: =IF(J6=1,N(I6)+ROW()/10000000,0) -> 3100 | L6: =IF(AND(J6=1,N(I6)>0),SUMIF($K$2:$K$5001,">="&K6,$I$2:$I$5001)/MAX(1,SUM($H$2:$H$5001)),"") -> 0.92145242 | M6: =IF($A6="","",INDEX($L$2:$L$5001,MATCH($A6,$A$2:$A$5001,0))) -> 0.92145242 | N6: =IF($A6="","",IF(N(M6)=0,"–",IF(M6<=Start!$D$20,"A",IF(M6<=Start!$D$21,"B","C")))) -> B | O6: =IF($A6="","",IF(NOT(ISNUMBER(F6)),"Wert fehlt; ",IF(F6<=0,"Wert ist 0; ",""))&IF(NOT(ISNUMBER(E6)),"Bestand fehlt; ",IF(E6<0,"Bestand negativ; ",IF(E6=0,"Nullbestand; ","")))&IF(D6="","Warengruppe fehlt; ","")&IF(B6="","Bezeichnung fehlt; ","")&IF(COUNTIFS($A$2:$A$5001,$A6,$C$2:$C$5001,C6)>1,"Artikel doppelt im selben Lager; ","")) | P6: =IF(OR($A6="",D6=""),0,IF(COUNTIF($D$2:D6,D6)=1,SUMIF($D$2:$D$5001,D6,$H$2:$H$5001)+ROW()/10000000,0)) -> 0 | Q6: =IF(OR($A6="",C6=""),0,IF(COUNTIF($C$2:C6,C6)=1,SUMIF($C$2:$C$5001,C6,$H$2:$H$5001)+ROW()/10000000,0)) -> 0
A7: 0001006 | B7: Dichtungssatz | C7: Hauptlager | D7: Dichtungen | E7: 12 | F7: 0 | G7: Stk | H7: =IF($A7="","",IF(OR(NOT(ISNUMBER(E7)),NOT(ISNUMBER(F7))),"",MAX(0,E7)*F7)) -> 0 | I7: =IF($A7="","",SUMIF($A$2:$A$5001,$A7,$H$2:$H$5001)) -> 9.6 | J7: =IF($A7="",0,IF(COUNTIF($A$2:A7,$A7)=1,1,0)) -> 1 | K7: =IF(J7=1,N(I7)+ROW()/10000000,0) -> 9.6000007 | L7: =IF(AND(J7=1,N(I7)>0),SUMIF($K$2:$K$5001,">="&K7,$I$2:$I$5001)/MAX(1,SUM($H$2:$H$5001)),"") -> 0.99997689 | M7: =IF($A7="","",INDEX($L$2:$L$5001,MATCH($A7,$A$2:$A$5001,0))) -> 0.99997689 | N7: =IF($A7="","",IF(N(M7)=0,"–",IF(M7<=Start!$D$20,"A",IF(M7<=Start!$D$21,"B","C")))) -> C | O7: =IF($A7="","",IF(NOT(ISNUMBER(F7)),"Wert fehlt; ",IF(F7<=0,"Wert ist 0; ",""))&IF(NOT(ISNUMBER(E7)),"Bestand fehlt; ",IF(E7<0,"Bestand negativ; ",IF(E7=0,"Nullbestand; ","")))&IF(D7="","Warengruppe fehlt; ","")&IF(B7="","Bezeichnung fehlt; ","")&IF(COUNTIFS($A$2:$A$5001,$A7,$C$2:$C$5001,C7)>1,"Artikel doppelt im selben Lager; ","")) -> Wert ist 0; | P7: =IF(OR($A7="",D7=""),0,IF(COUNTIF($D$2:D7,D7)=1,SUMIF($D$2:$D$5001,D7,$H$2:$H$5001)+ROW()/10000000,0)) -> 3082.6 | Q7: =IF(OR($A7="",C7=""),0,IF(COUNTIF($C$2:C7,C7)=1,SUMIF($C$2:$C$5001,C7,$H$2:$H$5001)+ROW()/10000000,0)) -> 0
A8: 0001006 | B8: Dichtungssatz | C8: Außenlager | D8: Dichtungen | E8: 4 | F8: 2.4 | G8: Stk | H8: =IF($A8="","",IF(OR(NOT(ISNUMBER(E8)),NOT(ISNUMBER(F8))),"",MAX(0,E8)*F8)) -> 9.6 | I8: =IF($A8="","",SUMIF($A$2:$A$5001,$A8,$H$2:$H$5001)) -> 9.6 | J8: =IF($A8="",0,IF(COUNTIF($A$2:A8,$A8)=1,1,0)) -> 0 | K8: =IF(J8=1,N(I8)+ROW()/10000000,0) -> 0 | L8: =IF(AND(J8=1,N(I8)>0),SUMIF($K$2:$K$5001,">="&K8,$I$2:$I$5001)/MAX(1,SUM($H$2:$H$5001)),"") | M8: =IF($A8="","",INDEX($L$2:$L$5001,MATCH($A8,$A$2:$A$5001,0))) -> 0.99997689 | N8: =IF($A8="","",IF(N(M8)=0,"–",IF(M8<=Start!$D$20,"A",IF(M8<=Start!$D$21,"B","C")))) -> C | O8: =IF($A8="","",IF(NOT(ISNUMBER(F8)),"Wert fehlt; ",IF(F8<=0,"Wert ist 0; ",""))&IF(NOT(ISNUMBER(E8)),"Bestand fehlt; ",IF(E8<0,"Bestand negativ; ",IF(E8=0,"Nullbestand; ","")))&IF(D8="","Warengruppe fehlt; ","")&IF(B8="","Bezeichnung fehlt; ","")&IF(COUNTIFS($A$2:$A$5001,$A8,$C$2:$C$5001,C8)>1,"Artikel doppelt im selben Lager; ","")) | P8: =IF(OR($A8="",D8=""),0,IF(COUNTIF($D$2:D8,D8)=1,SUMIF($D$2:$D$5001,D8,$H$2:$H$5001)+ROW()/10000000,0)) -> 0 | Q8: =IF(OR($A8="",C8=""),0,IF(COUNTIF($C$2:C8,C8)=1,SUMIF($C$2:$C$5001,C8,$H$2:$H$5001)+ROW()/10000000,0)) -> 21741.9
A9: 0001007 | B9: O-Ring-Sortiment | C9: Hauptlager | D9: Dichtungen | E9: 40 | F9: 14.9 | G9: Stk | H9: =IF($A9="","",IF(OR(NOT(ISNUMBER(E9)),NOT(ISNUMBER(F9))),"",MAX(0,E9)*F9)) -> 596 | I9: =IF($A9="","",SUMIF($A$2:$A$5001,$A9,$H$2:$H$5001)) -> 789.7 | J9: =IF($A9="",0,IF(COUNTIF($A$2:A9,$A9)=1,1,0)) -> 1 | K9: =IF(J9=1,N(I9)+ROW()/10000000,0) -> 789.7 | L9: =IF(AND(J9=1,N(I9)>0),SUMIF($K$2:$K$5001,">="&K9,$I$2:$I$5001)/MAX(1,SUM($H$2:$H$5001)),"") -> 0.98350617 | M9: =IF($A9="","",INDEX($L$2:$L$5001,MATCH($A9,$A$2:$A$5001,0))) -> 0.98350617 | N9: =IF($A9="","",IF(N(M9)=0,"–",IF(M9<=Start!$D$20,"A",IF(M9<=Start!$D$21,"B","C")))) -> C | O9: =IF($A9="","",IF(NOT(ISNUMBER(F9)),"Wert fehlt; ",IF(F9<=0,"Wert ist 0; ",""))&IF(NOT(ISNUMBER(E9)),"Bestand fehlt; ",IF(E9<0,"Bestand negativ; ",IF(E9=0,"Nullbestand; ","")))&IF(D9="","Warengruppe fehlt; ","")&IF(B9="","Bezeichnung fehlt; ","")&IF(COUNTIFS($A$2:$A$5001,$A9,$C$2:$C$5001,C9)>1,"Artikel doppelt im selben Lager; ","")) | P9: =IF(OR($A9="",D9=""),0,IF(COUNTIF($D$2:D9,D9)=1,SUMIF($D$2:$D$5001,D9,$H$2:$H$5001)+ROW()/10000000,0)) -> 0 | Q9: =IF(OR($A9="",C9=""),0,IF(COUNTIF($C$2:C9,C9)=1,SUMIF($C$2:$C$5001,C9,$H$2:$H$5001)+ROW()/10000000,0)) -> 0
A10: 0001007 | B10: O-Ring-Sortiment | C10: Außenlager | D10: Dichtungen | E10: 13 | F10: 14.9 | G10: Stk | H10: =IF($A10="","",IF(OR(NOT(ISNUMBER(E10)),NOT(ISNUMBER(F10))),"",MAX(0,E10)*F10)) -> 193.7 | I10: =IF($A10="","",SUMIF($A$2:$A$5001,$A10,$H$2:$H$5001)) -> 789.7 | J10: =IF($A10="",0,IF(COUNTIF($A$2:A10,$A10)=1,1,0)) -> 0 | K10: =IF(J10=1,N(I10)+ROW()/10000000,0) -> 0 | L10: =IF(AND(J10=1,N(I10)>0),SUMIF($K$2:$K$5001,">="&K10,$I$2:$I$5001)/MAX(1,SUM($H$2:$H$5001)),"") | M10: =IF($A10="","",INDEX($L$2:$L$5001,MATCH($A10,$A$2:$A$5001,0))) -> 0.98350617 | N10: =IF($A10="","",IF(N(M10)=0,"–",IF(M10<=Start!$D$20,"A",IF(M10<=Start!$D$21,"B","C")))) -> C | O10: =IF($A10="","",IF(NOT(ISNUMBER(F10)),"Wert fehlt; ",IF(F10<=0,"Wert ist 0; ",""))&IF(NOT(ISNUMBER(E10)),"Bestand fehlt; ",IF(E10<0,"Bestand negativ; ",IF(E10=0,"Nullbestand; ","")))&IF(D10="","Warengruppe fehlt; ","")&IF(B10="","Bezeichnung fehlt; ","")&IF(COUNTIFS($A$2:$A$5001,$A10,$C$2:$C$5001,C10)>1,"Artikel doppelt im selben Lager; ","")) | P10: =IF(OR($A10="",D10=""),0,IF(COUNTIF($D$2:D10,D10)=1,SUMIF($D$2:$D$5001,D10,$H$2:$H$5001)+ROW()/10000000,0)) -> 0 | Q10: =IF(OR($A10="",C10=""),0,IF(COUNTIF($C$2:C10,C10)=1,SUMIF($C$2:$C$5001,C10,$H$2:$H$5001)+ROW()/10000000,0)) -> 0
A11: 0001008 | B11: Wellendichtring | C11: Hauptlager | D11: Dichtungen | E11: 600 | F11: 3.8 | G11: Stk | H11: =IF($A11="","",IF(OR(NOT(ISNUMBER(E11)),NOT(ISNUMBER(F11))),"",MAX(0,E11)*F11)) -> 2280 | I11: =IF($A11="","",SUMIF($A$2:$A$5001,$A11,$H$2:$H$5001)) -> 2280 | J11: =IF($A11="",0,IF(COUNTIF($A$2:A11,$A11)=1,1,0)) -> 1 | K11: =IF(J11=1,N(I11)+ROW()/10000000,0) -> 2280 | L11: =IF(AND(J11=1,N(I11)>0),SUMIF($K$2:$K$5001,">="&K11,$I$2:$I$5001)/MAX(1,SUM($H$2:$H$5001)),"") -> 0.93742164 | M11: =IF($A11="","",INDEX($L$2:$L$5001,MATCH($A11,$A$2:$A$5001,0))) -> 0.93742164 | N11: =IF($A11="","",IF(N(M11)=0,"–",IF(M11<=Start!$D$20,"A",IF(M11<=Start!$D$21,"B","C")))) -> B | O11: =IF($A11="","",IF(NOT(ISNUMBER(F11)),"Wert fehlt; ",IF(F11<=0,"Wert ist 0; ",""))&IF(NOT(ISNUMBER(E11)),"Bestand fehlt; ",IF(E11<0,"Bestand negativ; ",IF(E11=0,"Nullbestand; ","")))&IF(D11="","Warengruppe fehlt; ","")&IF(B11="","Bezeichnung fehlt; ","")&IF(COUNTIFS($A$2:$A$5001,$A11,$C$2:$C$5001,C11)>1,"Artikel doppelt im selben Lager; ","")) | P11: =IF(OR($A11="",D11=""),0,IF(COUNTIF($D$2:D11,D11)=1,SUMIF($D$2:$D$5001,D11,$H$2:$H$5001)+ROW()/10000000,0)) -> 0 | Q11: =IF(OR($A11="",C11=""),0,IF(COUNTIF($C$2:C11,C11)=1,SUMIF($C$2:$C$5001,C11,$H$2:$H$5001)+ROW()/10000000,0)) -> 0
A12: 0001009 | B12: Flachdichtung DN50 | C12: Hauptlager | D12: Dichtungen | E12: 3 | F12: 1.1 | G12: Stk | H12: =IF($A12="","",IF(OR(NOT(ISNUMBER(E12)),NOT(ISNUMBER(F12))),"",MAX(0,E12)*F12)) -> 3.3 | I12: =IF($A12="","",SUMIF($A$2:$A$5001,$A12,$H$2:$H$5001)) -> 3.3 | J12: =IF($A12="",0,IF(COUNTIF($A$2:A12,$A12)=1,1,0)) -> 1 | K12: =IF(J12=1,N(I12)+ROW()/10000000,0) -> 3.3000012 | L12: =IF(AND(J12=1,N(I12)>0),SUMIF($K$2:$K$5001,">="&K12,$I$2:$I$5001)/MAX(1,SUM($H$2:$H$5001)),"") -> 1 | M12: =IF($A12="","",INDEX($L$2:$L$5001,MATCH($A12,$A$2:$A$5001,0))) -> 1 | N12: =IF($A12="","",IF(N(M12)=0,"–",IF(M12<=Start!$D$20,"A",IF(M12<=Start!$D$21,"B","C")))) -> C | O12: =IF($A12="","",IF(NOT(ISNUMBER(F12)),"Wert fehlt; ",IF(F12<=0,"Wert ist 0; ",""))&IF(NOT(ISNUMBER(E12)),"Bestand fehlt; ",IF(E12<0,"Bestand negativ; ",IF(E12=0,"Nullbestand; ","")))&IF(D12="","Warengruppe fehlt; ","")&IF(B12="","Bezeichnung fehlt; ","")&IF(COUNTIFS($A$2:$A$5001,$A12,$C$2:$C$5001,C12)>1,"Artikel doppelt im selben Lager; ","")) | P12: =IF(OR($A12="",D12=""),0,IF(COUNTIF($D$2:D12,D12)=1,SUMIF($D$2:$D$5001,D12,$H$2:$H$5001)+ROW()/10000000,0)) -> 0 | Q12: =IF(OR($A12="",C12=""),0,IF(COUNTIF($C$2:C12,C12)=1,SUMIF($C$2:$C$5001,C12,$H$2:$H$5001)+ROW()/10000000,0)) -> 0
A13: 0001010 | B13: Industriepumpe | C13: Hauptlager | D13: Pumpen | E13: -4 | F13: 1250 | G13: Stk | H13: =IF($A13="","",IF(OR(NOT(ISNUMBER(E13)),NOT(ISNUMBER(F13))),"",MAX(0,E13)*F13)) -> 0 | I13: =IF($A13="","",SUMIF($A$2:$A$5001,$A13,$H$2:$H$5001)) -> 0 | J13: =IF($A13="",0,IF(COUNTIF($A$2:A13,$A13)=1,1,0)) -> 1 | K13: =IF(J13=1,N(I13)+ROW()/10000000,0) -> 1.3e-06 | L13: =IF(AND(J13=1,N(I13)>0),SUMIF($K$2:$K$5001,">="&K13,$I$2:$I$5001)/MAX(1,SUM($H$2:$H$5001)),"") | M13: =IF($A13="","",INDEX($L$2:$L$5001,MATCH($A13,$A$2:$A$5001,0))) | N13: =IF($A13="","",IF(N(M13)=0,"–",IF(M13<=Start!$D$20,"A",IF(M13<=Start!$D$21,"B","C")))) -> – | O13: =IF($A13="","",IF(NOT(ISNUMBER(F13)),"Wert fehlt; ",IF(F13<=0,"Wert ist 0; ",""))&IF(NOT(ISNUMBER(E13)),"Bestand fehlt; ",IF(E13<0,"Bestand negativ; ",IF(E13=0,"Nullbestand; ","")))&IF(D13="","Warengruppe fehlt; ","")&IF(B13="","Bezeichnung fehlt; ","")&IF(COUNTIFS($A$2:$A$5001,$A13,$C$2:$C$5001,C13)>1,"Artikel doppelt im selben Lager; ","")) -> Bestand negativ; | P13: =IF(OR($A13="",D13=""),0,IF(COUNTIF($D$2:D13,D13)=1,SUMIF($D$2:$D$5001,D13,$H$2:$H$5001)+ROW()/10000000,0)) -> 10890 | Q13: =IF(OR($A13="",C13=""),0,IF(COUNTIF($C$2:C13,C13)=1,SUMIF($C$2:$C$5001,C13,$H$2:$H$5001)+ROW()/10000000,0)) -> 0
... A18: 0001014 | B18: Kugellager 6205 | C18: Hauptlager | D18: Lager | E18: 8 | F18: 6.8 | G18: Stk | H18: =IF($A18="","",IF(OR(NOT(ISNUMBER(E18)),NOT(ISNUMBER(F18))),"",MAX(0,E18)*F18)) -> 54.4 | I18: =IF($A18="","",SUMIF($A$2:$A$5001,$A18,$H$2:$H$5001)) -> 68 | J18: =IF($A18="",0,IF(COUNTIF($A$2:A18,$A18)=1,1,0)) -> 1 | K18: =IF(J18=1,N(I18)+ROW()/10000000,0) -> 68.000002 | L18: =IF(AND(J18=1,N(I18)>0),SUMIF($K$2:$K$5001,">="&K18,$I$2:$I$5001)/MAX(1,SUM($H$2:$H$5001)),"") -> 0.99956785 | M18: =IF($A18="","",INDEX($L$2:$L$5001,MATCH($A18,$A$2:$A$5001,0))) -> 0.99956785 | N18: =IF($A18="","",IF(N(M18)=0,"–",IF(M18<=Start!$D$20,"A",IF(M18<=Start!$D$21,"B","C")))) -> C | O18: =IF($A18="","",IF(NOT(ISNUMBER(F18)),"Wert fehlt; ",IF(F18<=0,"Wert ist 0; ",""))&IF(NOT(ISNUMBER(E18)),"Bestand fehlt; ",IF(E18<0,"Bestand negativ; ",IF(E18=0,"Nullbestand; ","")))&IF(D18="","Warengruppe fehlt; ","")&IF(B18="","Bezeichnung fehlt; ","")&IF(COUNTIFS($A$2:$A$5001,$A18,$C$2:$C$5001,C18)>1,"Artikel doppelt im selben Lager; ","")) | P18: =IF(OR($A18="",D18=""),0,IF(COUNTIF($D$2:D18,D18)=1,SUMIF($D$2:$D$5001,D18,$H$2:$H$5001)+ROW()/10000000,0)) -> 61592.4 | Q18: =IF(OR($A18="",C18=""),0,IF(COUNTIF($C$2:C18,C18)=1,SUMIF($C$2:$C$5001,C18,$H$2:$H$5001)+ROW()/10000000,0)) -> 0
A19: 0001014 | B19: Kugellager 6205 | C19: Außenlager | E19: 2 | F19: 6.8 | G19: Stk | H19: =IF($A19="","",IF(OR(NOT(ISNUMBER(E19)),NOT(ISNUMBER(F19))),"",MAX(0,E19)*F19)) -> 13.6 | I19: =IF($A19="","",SUMIF($A$2:$A$5001,$A19,$H$2:$H$5001)) -> 68 | J19: =IF($A19="",0,IF(COUNTIF($A$2:A19,$A19)=1,1,0)) -> 0 | K19: =IF(J19=1,N(I19)+ROW()/10000000,0) -> 0 | L19: =IF(AND(J19=1,N(I19)>0),SUMIF($K$2:$K$5001,">="&K19,$I$2:$I$5001)/MAX(1,SUM($H$2:$H$5001)),"") | M19: =IF($A19="","",INDEX($L$2:$L$5001,MATCH($A19,$A$2:$A$5001,0))) -> 0.99956785 | N19: =IF($A19="","",IF(N(M19)=0,"–",IF(M19<=Start!$D$20,"A",IF(M19<=Start!$D$21,"B","C")))) -> C | O19: =IF($A19="","",IF(NOT(ISNUMBER(F19)),"Wert fehlt; ",IF(F19<=0,"Wert ist 0; ",""))&IF(NOT(ISNUMBER(E19)),"Bestand fehlt; ",IF(E19<0,"Bestand negativ; ",IF(E19=0,"Nullbestand; ","")))&IF(D19="","Warengruppe fehlt; ","")&IF(B19="","Bezeichnung fehlt; ","")&IF(COUNTIFS($A$2:$A$5001,$A19,$C$2:$C$5001,C19)>1,"Artikel doppelt im selben Lager; ","")) -> Warengruppe fehlt; | P19: =IF(OR($A19="",D19=""),0,IF(COUNTIF($D$2:D19,D19)=1,SUMIF($D$2:$D$5001,D19,$H$2:$H$5001)+ROW()/10000000,0)) -> 0 | Q19: =IF(OR($A19="",C19=""),0,IF(COUNTIF($C$2:C19,C19)=1,SUMIF($C$2:$C$5001,C19,$H$2:$H$5001)+ROW()/10000000,0)) -> 0
A20: 0001015 | B20: Pendelrollenlager | C20: Hauptlager | D20: Lager | E20: 2 | F20: 94 | G20: Stk | H20: =IF($A20="","",IF(OR(NOT(ISNUMBER(E20)),NOT(ISNUMBER(F20))),"",MAX(0,E20)*F20)) -> 188 | I20: =IF($A20="","",SUMIF($A$2:$A$5001,$A20,$H$2:$H$5001)) -> 188 | J20: =IF($A20="",0,IF(COUNTIF($A$2:A20,$A20)=1,1,0)) -> 1 | K20: =IF(J20=1,N(I20)+ROW()/10000000,0) -> 188 | L20: =IF(AND(J20=1,N(I20)>0),SUMIF($K$2:$K$5001,">="&K20,$I$2:$I$5001)/MAX(1,SUM($H$2:$H$5001)),"") -> 0.99780843 | M20: =IF($A20="","",INDEX($L$2:$L$5001,MATCH($A20,$A$2:$A$5001,0))) -> 0.99780843 | N20: =IF($A20="","",IF(N(M20)=0,"–",IF(M20<=Start!$D$20,"A",IF(M20<=Start!$D$21,"B","C")))) -> C | O20: =IF($A20="","",IF(NOT(ISNUMBER(F20)),"Wert fehlt; ",IF(F20<=0,"Wert ist 0; ",""))&IF(NOT(ISNUMBER(E20)),"Bestand fehlt; ",IF(E20<0,"Bestand negativ; ",IF(E20=0,"Nullbestand; ","")))&IF(D20="","Warengruppe fehlt; ","")&IF(B20="","Bezeichnung fehlt; ","")&IF(COUNTIFS($A$2:$A$5001,$A20,$C$2:$C$5001,C20)>1,"Artikel doppelt im selben Lager; ","")) | P20: =IF(OR($A20="",D20=""),0,IF(COUNTIF($D$2:D20,D20)=1,SUMIF($D$2:$D$5001,D20,$H$2:$H$5001)+ROW()/10000000,0)) -> 0 | Q20: =IF(OR($A20="",C20=""),0,IF(COUNTIF($C$2:C20,C20)=1,SUMIF($C$2:$C$5001,C20,$H$2:$H$5001)+ROW()/10000000,0)) -> 0
A21: 0001016 | B21: Stehlagereinheit | C21: Hauptlager | D21: Lager | E21: 1200 | F21: 38 | G21: Stk | H21: =IF($A21="","",IF(OR(NOT(ISNUMBER(E21)),NOT(ISNUMBER(F21))),"",MAX(0,E21)*F21)) -> 45600 | I21: =IF($A21="","",SUMIF($A$2:$A$5001,$A21,$H$2:$H$5001)) -> 60800 | J21: =IF($A21="",0,IF(COUNTIF($A$2:A21,$A21)=1,1,0)) -> 1 | K21: =IF(J21=1,N(I21)+ROW()/10000000,0) -> 60800 | L21: =IF(AND(J21=1,N(I21)>0),SUMIF($K$2:$K$5001,">="&K21,$I$2:$I$5001)/MAX(1,SUM($H$2:$H$5001)),"") -> 0.42584605 | M21: =IF($A21="","",INDEX($L$2:$L$5001,MATCH($A21,$A$2:$A$5001,0))) -> 0.42584605 | N21: =IF($A21="","",IF(N(M21)=0,"–",IF(M21<=Start!$D$20,"A",IF(M21<=Start!$D$21,"B","C")))) -> A | O21: =IF($A21="","",IF(NOT(ISNUMBER(F21)),"Wert fehlt; ",IF(F21<=0,"Wert ist 0; ",""))&IF(NOT(ISNUMBER(E21)),"Bestand fehlt; ",IF(E21<0,"Bestand negativ; ",IF(E21=0,"Nullbestand; ","")))&IF(D21="","Warengruppe fehlt; ","")&IF(B21="","Bezeichnung fehlt; ","")&IF(COUNTIFS($A$2:$A$5001,$A21,$C$2:$C$5001,C21)>1,"Artikel doppelt im selben Lager; ","")) | P21: =IF(OR($A21="",D21=""),0,IF(COUNTIF($D$2:D21,D21)=1,SUMIF($D$2:$D$5001,D21,$H$2:$H$5001)+ROW()/10000000,0)) -> 0 | Q21: =IF(OR($A21="",C21=""),0,IF(COUNTIF($C$2:C21,C21)=1,SUMIF($C$2:$C$5001,C21,$H$2:$H$5001)+ROW()/10000000,0)) -> 0
A22: 0001016 | B22: Stehlagereinheit | C22: Außenlager | D22: Lager | E22: 400 | F22: 38 | G22: Stk | H22: =IF($A22="","",IF(OR(NOT(ISNUMBER(E22)),NOT(ISNUMBER(F22))),"",MAX(0,E22)*F22)) -> 15200 | I22: =IF($A22="","",SUMIF($A$2:$A$5001,$A22,$H$2:$H$5001)) -> 60800 | J22: =IF($A22="",0,IF(COUNTIF($A$2:A22,$A22)=1,1,0)) -> 0 | K22: =IF(J22=1,N(I22)+ROW()/10000000,0) -> 0 | L22: =IF(AND(J22=1,N(I22)>0),SUMIF($K$2:$K$5001,">="&K22,$I$2:$I$5001)/MAX(1,SUM($H$2:$H$5001)),"") | M22: =IF($A22="","",INDEX($L$2:$L$5001,MATCH($A22,$A$2:$A$5001,0))) -> 0.42584605 | N22: =IF($A22="","",IF(N(M22)=0,"–",IF(M22<=Start!$D$20,"A",IF(M22<=Start!$D$21,"B","C")))) -> A | O22: =IF($A22="","",IF(NOT(ISNUMBER(F22)),"Wert fehlt; ",IF(F22<=0,"Wert ist 0; ",""))&IF(NOT(ISNUMBER(E22)),"Bestand fehlt; ",IF(E22<0,"Bestand negativ; ",IF(E22=0,"Nullbestand; ","")))&IF(D22="","Warengruppe fehlt; ","")&IF(B22="","Bezeichnung fehlt; ","")&IF(COUNTIFS($A$2:$A$5001,$A22,$C$2:$C$5001,C22)>1,"Artikel doppelt im selben Lager; ","")) | P22: =IF(OR($A22="",D22=""),0,IF(COUNTIF($D$2:D22,D22)=1,SUMIF($D$2:$D$5001,D22,$H$2:$H$5001)+ROW()/10000000,0)) -> 0 | Q22: =IF(OR($A22="",C22=""),0,IF(COUNTIF($C$2:C22,C22)=1,SUMIF($C$2:$C$5001,C22,$H$2:$H$5001)+ROW()/10000000,0)) -> 0
A23: 0001017 | B23: Nadelhülse | C23: Hauptlager | D23: Lager | E23: 250 | F23: 2.2 | G23: Stk | H23: =IF($A23="","",IF(OR(NOT(ISNUMBER(E23)),NOT(ISNUMBER(F23))),"",MAX(0,E23)*F23)) -> 550 | I23: =IF($A23="","",SUMIF($A$2:$A$5001,$A23,$H$2:$H$5001)) -> 550 | J23: =IF($A23="",0,IF(COUNTIF($A$2:A23,$A23)=1,1,0)) -> 1 | K23: =IF(J23=1,N(I23)+ROW()/10000000,0) -> 550 | L23: =IF(AND(J23=1,N(I23)>0),SUMIF($K$2:$K$5001,">="&K23,$I$2:$I$5001)/MAX(1,SUM($H$2:$H$5001)),"") -> 0.9873584 | M23: =IF($A23="","",INDEX($L$2:$L$5001,MATCH($A23,$A$2:$A$5001,0))) -> 0.9873584 | N23: =IF($A23="","",IF(N(M23)=0,"–",IF(M23<=Start!$D$20,"A",IF(M23<=Start!$D$21,"B","C")))) -> C | O23: =IF($A23="","",IF(NOT(ISNUMBER(F23)),"Wert fehlt; ",IF(F23<=0,"Wert ist 0; ",""))&IF(NOT(ISNUMBER(E23)),"Bestand fehlt; ",IF(E23<0,"Bestand negativ; ",IF(E23=0,"Nullbestand; ","")))&IF(D23="","Warengruppe fehlt; ","")&IF(B23="","Bezeichnung fehlt; ","")&IF(COUNTIFS($A$2:$A$5001,$A23,$C$2:$C$5001,C23)>1,"Artikel doppelt im selben Lager; ","")) | P23: =IF(OR($A23="",D23=""),0,IF(COUNTIF($D$2:D23,D23)=1,SUMIF($D$2:$D$5001,D23,$H$2:$H$5001)+ROW()/10000000,0)) -> 0 | Q23: =IF(OR($A23="",C23=""),0,IF(COUNTIF($C$2:C23,C23)=1,SUMIF($C$2:$C$5001,C23,$H$2:$H$5001)+ROW()/10000000,0)) -> 0
A24: 0001018 | B24: Keilriemen SPZ | C24: Hauptlager | D24: Antriebstechnik | E24: 1200 | F24: 9.6 | G24: Stk | H24: =IF($A24="","",IF(OR(NOT(ISNUMBER(E24)),NOT(ISNUMBER(F24))),"",MAX(0,E24)*F24)) -> 11520 | I24: =IF($A24="","",SUMIF($A$2:$A$5001,$A24,$H$2:$H$5001)) -> 11520 | J24: =IF($A24="",0,IF(COUNTIF($A$2:A24,$A24)=1,1,0)) -> 1 | K24: =IF(J24=1,N(I24)+ROW()/10000000,0) -> 11520 | L24: =IF(AND(J24=1,N(I24)>0),SUMIF($K$2:$K$5001,">="&K24,$I$2:$I$5001)/MAX(1,SUM($H$2:$H$5001)),"") -> 0.74274416 | M24: =IF($A24="","",INDEX($L$2:$L$5001,MATCH($A24,$A$2:$A$5001,0))) -> 0.74274416 | N24: =IF($A24="","",IF(N(M24)=0,"–",IF(M24<=Start!$D$20,"A",IF(M24<=Start!$D$21,"B","C")))) -> A | O24: =IF($A24="","",IF(NOT(ISNUMBER(F24)),"Wert fehlt; ",IF(F24<=0,"Wert ist 0; ",""))&IF(NOT(ISNUMBER(E24)),"Bestand fehlt; ",IF(E24<0,"Bestand negativ; ",IF(E24=0,"Nullbestand; ","")))&IF(D24="","Warengruppe fehlt; ","")&IF(B24="","Bezeichnung fehlt; ","")&IF(COUNTIFS($A$2:$A$5001,$A24,$C$2:$C$5001,C24)>1,"Artikel doppelt im selben Lager; ","")) | P24: =IF(OR($A24="",D24=""),0,IF(COUNTIF($D$2:D24,D24)=1,SUMIF($D$2:$D$5001,D24,$H$2:$H$5001)+ROW()/10000000,0)) -> 35396 | Q24: =IF(OR($A24="",C24=""),0,IF(COUNTIF($C$2:C24,C24)=1,SUMIF($C$2:$C$5001,C24,$H$2:$H$5001)+ROW()/10000000,0)) -> 0
A25: 0001019 | B25: Zahnriemen | C25: Hauptlager | D25: Antriebstechnik | E25: 600 | F25: 27 | G25: Stk | H25: =IF($A25="","",IF(OR(NOT(ISNUMBER(E25)),NOT(ISNUMBER(F25))),"",MAX(0,E25)*F25)) -> 16200 | I25: =IF($A25="","",SUMIF($A$2:$A$5001,$A25,$H$2:$H$5001)) -> 21600 | J25: =IF($A25="",0,IF(COUNTIF($A$2:A25,$A25)=1,1,0)) -> 1 | K25: =IF(J25=1,N(I25)+ROW()/10000000,0) -> 21600 | L25: =IF(AND(J25=1,N(I25)>0),SUMIF($K$2:$K$5001,">="&K25,$I$2:$I$5001)/MAX(1,SUM($H$2:$H$5001)),"") -> 0.57713347 | M25: =IF($A25="","",INDEX($L$2:$L$5001,MATCH($A25,$A$2:$A$5001,0))) -> 0.57713347 | N25: =IF($A25="","",IF(N(M25)=0,"–",IF(M25<=Start!$D$20,"A",IF(M25<=Start!$D$21,"B","C")))) -> A | O25: =IF($A25="","",IF(NOT(ISNUMBER(F25)),"Wert fehlt; ",IF(F25<=0,"Wert ist 0; ",""))&IF(NOT(ISNUMBER(E25)),"Bestand fehlt; ",IF(E25<0,"Bestand negativ; ",IF(E25=0,"Nullbestand; ","")))&IF(D25="","Warengruppe fehlt; ","")&IF(B25="","Bezeichnung fehlt; ","")&IF(COUNTIFS($A$2:$A$5001,$A25,$C$2:$C$5001,C25)>1,"Artikel doppelt im selben Lager; ","")) | P25: =IF(OR($A25="",D25=""),0,IF(COUNTIF($D$2:D25,D25)=1,SUMIF($D$2:$D$5001,D25,$H$2:$H$5001)+ROW()/10000000,0)) -> 0 | Q25: =IF(OR($A25="",C25=""),0,IF(COUNTIF($C$2:C25,C25)=1,SUMIF($C$2:$C$5001,C25,$H$2:$H$5001)+ROW()/10000000,0)) -> 0
A26: 0001019 | B26: Zahnriemen | C26: Außenlager | D26: Antriebstechnik | E26: 200 | F26: 27 | G26: Stk | H26: =IF($A26="","",IF(OR(NOT(ISNUMBER(E26)),NOT(ISNUMBER(F26))),"",MAX(0,E26)*F26)) -> 5400 | I26: =IF($A26="","",SUMIF($A$2:$A$5001,$A26,$H$2:$H$5001)) -> 21600 | J26: =IF($A26="",0,IF(COUNTIF($A$2:A26,$A26)=1,1,0)) -> 0 | K26: =IF(J26=1,N(I26)+ROW()/10000000,0) -> 0 | L26: =IF(AND(J26=1,N(I26)>0),SUMIF($K$2:$K$5001,">="&K26,$I$2:$I$5001)/MAX(1,SUM($H$2:$H$5001)),"") | M26: =IF($A26="","",INDEX($L$2:$L$5001,MATCH($A26,$A$2:$A$5001,0))) -> 0.57713347 | N26: =IF($A26="","",IF(N(M26)=0,"–",IF(M26<=Start!$D$20,"A",IF(M26<=Start!$D$21,"B","C")))) -> A | O26: =IF($A26="","",IF(NOT(ISNUMBER(F26)),"Wert fehlt; ",IF(F26<=0,"Wert ist 0; ",""))&IF(NOT(ISNUMBER(E26)),"Bestand fehlt; ",IF(E26<0,"Bestand negativ; ",IF(E26=0,"Nullbestand; ","")))&IF(D26="","Warengruppe fehlt; ","")&IF(B26="","Bezeichnung fehlt; ","")&IF(COUNTIFS($A$2:$A$5001,$A26,$C$2:$C$5001,C26)>1,"Artikel doppelt im selben Lager; ","")) | P26: =IF(OR($A26="",D26=""),0,IF(COUNTIF($D$2:D26,D26)=1,SUMIF($D$2:$D$5001,D26,$H$2:$H$5001)+ROW()/10000000,0)) -> 0 | Q26: =IF(OR($A26="",C26=""),0,IF(COUNTIF($C$2:C26,C26)=1,SUMIF($C$2:$C$5001,C26,$H$2:$H$5001)+ROW()/10000000,0)) -> 0
A27: 0001020 | B27: Getriebemotor 0,75 kW | C27: Hauptlager | D27: Antriebstechnik | E27: 4 | F27: 560 | G27: Stk | H27: =IF($A27="","",IF(OR(NOT(ISNUMBER(E27)),NOT(ISNUMBER(F27))),"",MAX(0,E27)*F27)) -> 2240 | I27: =IF($A27="","",SUMIF($A$2:$A$5001,$A27,$H$2:$H$5001)) -> 2240 | J27: =IF($A27="",0,IF(COUNTIF($A$2:A27,$A27)=1,1,0)) -> 1 | K27: =IF(J27=1,N(I27)+ROW()/10000000,0) -> 2240 | L27: =IF(AND(J27=1,N(I27)>0),SUMIF($K$2:$K$5001,">="&K27,$I$2:$I$5001)/MAX(1,SUM($H$2:$H$5001)),"") -> 0.95311071 | M27: =IF($A27="","",INDEX($L$2:$L$5001,MATCH($A27,$A$2:$A$5001,0))) -> 0.95311071 | N27: =IF($A27="","",IF(N(M27)=0,"–",IF(M27<=Start!$D$20,"A",IF(M27<=Start!$D$21,"B","C")))) -> C | O27: =IF($A27="","",IF(NOT(ISNUMBER(F27)),"Wert fehlt; ",IF(F27<=0,"Wert ist 0; ",""))&IF(NOT(ISNUMBER(E27)),"Bestand fehlt; ",IF(E27<0,"Bestand negativ; ",IF(E27=0,"Nullbestand; ","")))&IF(D27="","Warengruppe fehlt; ","")&IF(B27="","Bezeichnung fehlt; ","")&IF(COUNTIFS($A$2:$A$5001,$A27,$C$2:$C$5001,C27)>1,"Artikel doppelt im selben Lager; ","")) | P27: =IF(OR($A27="",D27=""),0,IF(COUNTIF($D$2:D27,D27)=1,SUMIF($D$2:$D$5001,D27,$H$2:$H$5001)+ROW()/10000000,0)) -> 0 | Q27: =IF(OR($A27="",C27=""),0,IF(COUNTIF($C$2:C27,C27)=1,SUMIF($C$2:$C$5001,C27,$H$2:$H$5001)+ROW()/10000000,0)) -> 0
A28: 0001021 | B28: Kupplungsstern | C28: Hauptlager | D28: Antriebstechnik | E28: 8 | F28: 4.5 | G28: Stk | H28: =IF($A28="","",IF(OR(NOT(ISNUMBER(E28)),NOT(ISNUMBER(F28))),"",MAX(0,E28)*F28)) -> 36 | I28: =IF($A28="","",SUMIF($A$2:$A$5001,$A28,$H$2:$H$5001)) -> 36 | J28: =IF($A28="",0,IF(COUNTIF($A$2:A28,$A28)=1,1,0)) -> 1 | K28: =IF(J28=1,N(I28)+ROW()/10000000,0) -> 36.000003 | L28: =IF(AND(J28=1,N(I28)>0),SUMIF($K$2:$K$5001,">="&K28,$I$2:$I$5001)/MAX(1,SUM($H$2:$H$5001)),"") -> 0.99982 | M28: =IF($A28="","",INDEX($L$2:$L$5001,MATCH($A28,$A$2:$A$5001,0))) -> 0.99982 | N28: =IF($A28="","",IF(N(M28)=0,"–",IF(M28<=Start!$D$20,"A",IF(M28<=Start!$D$21,"B","C")))) -> C | O28: =IF($A28="","",IF(NOT(ISNUMBER(F28)),"Wert fehlt; ",IF(F28<=0,"Wert ist 0; ",""))&IF(NOT(ISNUMBER(E28)),"Bestand fehlt; ",IF(E28<0,"Bestand negativ; ",IF(E28=0,"Nullbestand; ","")))&IF(D28="","Warengruppe fehlt; ","")&IF(B28="","Bezeichnung fehlt; ","")&IF(COUNTIFS($A$2:$A$5001,$A28,$C$2:$C$5001,C28)>1,"Artikel doppelt im selben Lager; ","")) | P28: =IF(OR($A28="",D28=""),0,IF(COUNTIF($D$2:D28,D28)=1,SUMIF($D$2:$D$5001,D28,$H$2:$H$5001)+ROW()/10000000,0)) -> 0 | Q28: =IF(OR($A28="",C28=""),0,IF(COUNTIF($C$2:C28,C28)=1,SUMIF($C$2:$C$5001,C28,$H$2:$H$5001)+ROW()/10000000,0)) -> 0
A29: 0001022 | B29: Fett 1 kg | C29: Hauptlager | D29: Schmierstoffe | E29: 40 | F29: 11.5 | G29: Stk | H29: =IF($A29="","",IF(OR(NOT(ISNUMBER(E29)),NOT(ISNUMBER(F29))),"",MAX(0,E29)*F29)) -> 460 | I29: =IF($A29="","",SUMIF($A$2:$A$5001,$A29,$H$2:$H$5001)) -> 460 | J29: =IF($A29="",0,IF(COUNTIF($A$2:A29,$A29)=1,1,0)) -> 1 | K29: =IF(J29=1,N(I29)+ROW()/10000000,0) -> 460 | L29: =IF(AND(J29=1,N(I29)>0),SUMIF($K$2:$K$5001,">="&K29,$I$2:$I$5001)/MAX(1,SUM($H$2:$H$5001)),"") -> 0.99436244 | M29: =IF($A29="","",INDEX($L$2:$L$5001,MATCH($A29,$A$2:$A$5001,0))) -> 0.99436244 | N29: =IF($A29="","",IF(N(M29)=0,"–",IF(M29<=Start!$D$20,"A",IF(M29<=Start!$D$21,"B","C")))) -> C | O29: =IF($A29="","",IF(NOT(ISNUMBER(F29)),"Wert fehlt; ",IF(F29<=0,"Wert ist 0; ",""))&IF(NOT(ISNUMBER(E29)),"Bestand fehlt; ",IF(E29<0,"Bestand negativ; ",IF(E29=0,"Nullbestand; ","")))&IF(D29="","Warengruppe fehlt; ","")&IF(B29="","Bezeichnung fehlt; ","")&IF(COUNTIFS($A$2:$A$5001,$A29,$C$2:$C$5001,C29)>1,"Artikel doppelt im selben Lager; ","")) | P29: =IF(OR($A29="",D29=""),0,IF(COUNTIF($D$2:D29,D29)=1,SUMIF($D$2:$D$5001,D29,$H$2:$H$5001)+ROW()/10000000,0)) -> 1911.2 | Q29: =IF(OR($A29="",C29=""),0,IF(COUNTIF($C$2:C29,C29)=1,SUMIF($C$2:$C$5001,C29,$H$2:$H$5001)+ROW()/10000000,0)) -> 0
A30: 0001023 | B30: Getriebeöl 20 l | C30: Hauptlager | D30: Schmierstoffe | E30: 10 | F30: 138 | G30: Stk | H30: =IF($A30="","",IF(OR(NOT(ISNUMBER(E30)),NOT(ISNUMBER(F30))),"",MAX(0,E30)*F30)) -> 1380 | I30: =IF($A30="","",SUMIF($A$2:$A$5001,$A30,$H$2:$H$5001)) -> 1380 | J30: =IF($A30="",0,IF(COUNTIF($A$2:A30,$A30)=1,1,0)) -> 1 | K30: =IF(J30=1,N(I30)+ROW()/10000000,0) -> 1380 | L30: =IF(AND(J30=1,N(I30)>0),SUMIF($K$2:$K$5001,">="&K30,$I$2:$I$5001)/MAX(1,SUM($H$2:$H$5001)),"") -> 0.96277629 | M30: =IF($A30="","",INDEX($L$2:$L$5001,MATCH($A30,$A$2:$A$5001,0))) -> 0.96277629 | N30: =IF($A30="","",IF(N(M30)=0,"–",IF(M30<=Start!$D$20,"A",IF(M30<=Start!$D$21,"B","C")))) -> C | O30: =IF($A30="","",IF(NOT(ISNUMBER(F30)),"Wert fehlt; ",IF(F30<=0,"Wert ist 0; ",""))&IF(NOT(ISNUMBER(E30)),"Bestand fehlt; ",IF(E30<0,"Bestand negativ; ",IF(E30=0,"Nullbestand; ","")))&IF(D30="","Warengruppe fehlt; ","")&IF(B30="","Bezeichnung fehlt; ","")&IF(COUNTIFS($A$2:$A$5001,$A30,$C$2:$C$5001,C30)>1,"Artikel doppelt im selben Lager; ","")) | P30: =IF(OR($A30="",D30=""),0,IF(COUNTIF($D$2:D30,D30)=1,SUMIF($D$2:$D$5001,D30,$H$2:$H$5001)+ROW()/10000000,0)) -> 0 | Q30: =IF(OR($A30="",C30=""),0,IF(COUNTIF($C$2:C30,C30)=1,SUMIF($C$2:$C$5001,C30,$H$2:$H$5001)+ROW()/10000000,0)) -> 0
A31: 0001024 | B31: Kettenspray | C31: Hauptlager | D31: Schmierstoffe | E31: 8 | F31: 8.9 | G31: Stk | H31: =IF($A31="","",IF(OR(NOT(ISNUMBER(E31)),NOT(ISNUMBER(F31))),"",MAX(0,E31)*F31)) -> 71.2 | I31: =IF($A31="","",SUMIF($A$2:$A$5001,$A31,$H$2:$H$5001)) -> 71.2 | J31: =IF($A31="",0,IF(COUNTIF($A$2:A31,$A31)=1,1,0)) -> 1 | K31: =IF(J31=1,N(I31)+ROW()/10000000,0) -> 71.200003 | L31: =IF(AND(J31=1,N(I31)>0),SUMIF($K$2:$K$5001,">="&K31,$I$2:$I$5001)/MAX(1,SUM($H$2:$H$5001)),"") -> 0.99909158 | M31: =IF($A31="","",INDEX($L$2:$L$5001,MATCH($A31,$A$2:$A$5001,0))) -> 0.99909158 | N31: =IF($A31="","",IF(N(M31)=0,"–",IF(M31<=Start!$D$20,"A",IF(M31<=Start!$D$21,"B","C")))) -> C | O31: =IF($A31="","",IF(NOT(ISNUMBER(F31)),"Wert fehlt; ",IF(F31<=0,"Wert ist 0; ",""))&IF(NOT(ISNUMBER(E31)),"Bestand fehlt; ",IF(E31<0,"Bestand negativ; ",IF(E31=0,"Nullbestand; ","")))&IF(D31="","Warengruppe fehlt; ","")&IF(B31="","Bezeichnung fehlt; ","")&IF(COUNTIFS($A$2:$A$5001,$A31,$C$2:$C$5001,C31)>1,"Artikel doppelt im selben Lager; ","")) | P31: =IF(OR($A31="",D31=""),0,IF(COUNTIF($D$2:D31,D31)=1,SUMIF($D$2:$D$5001,D31,$H$2:$H$5001)+ROW()/10000000,0)) -> 0 | Q31: =IF(OR($A31="",C31=""),0,IF(COUNTIF($C$2:C31,C31)=1,SUMIF($C$2:$C$5001,C31,$H$2:$H$5001)+ROW()/10000000,0)) -> 0
... A35: 0001028 | B35: Steckverbinder 8 mm | C35: Hauptlager | D35: Pneumatik | E35: 8 | F35: 1.6 | G35: Stk | H35: =IF($A35="","",IF(OR(NOT(ISNUMBER(E35)),NOT(ISNUMBER(F35))),"",MAX(0,E35)*F35)) -> 12.8 | I35: =IF($A35="","",SUMIF($A$2:$A$5001,$A35,$H$2:$H$5001)) -> 12.8 | J35: =IF($A35="",0,IF(COUNTIF($A$2:A35,$A35)=1,1,0)) -> 1 | K35: =IF(J35=1,N(I35)+ROW()/10000000,0) -> 12.800004 | L35: =IF(AND(J35=1,N(I35)>0),SUMIF($K$2:$K$5001,">="&K35,$I$2:$I$5001)/MAX(1,SUM($H$2:$H$5001)),"") -> 0.99990965 | M35: =IF($A35="","",INDEX($L$2:$L$5001,MATCH($A35,$A$2:$A$5001,0))) -> 0.99990965 | N35: =IF($A35="","",IF(N(M35)=0,"–",IF(M35<=Start!$D$20,"A",IF(M35<=Start!$D$21,"B","C")))) -> C | O35: =IF($A35="","",IF(NOT(ISNUMBER(F35)),"Wert fehlt; ",IF(F35<=0,"Wert ist 0; ",""))&IF(NOT(ISNUMBER(E35)),"Bestand fehlt; ",IF(E35<0,"Bestand negativ; ",IF(E35=0,"Nullbestand; ","")))&IF(D35="","Warengruppe fehlt; ","")&IF(B35="","Bezeichnung fehlt; ","")&IF(COUNTIFS($A$2:$A$5001,$A35,$C$2:$C$5001,C35)>1,"Artikel doppelt im selben Lager; ","")) | P35: =IF(OR($A35="",D35=""),0,IF(COUNTIF($D$2:D35,D35)=1,SUMIF($D$2:$D$5001,D35,$H$2:$H$5001)+ROW()/10000000,0)) -> 0 | Q35: =IF(OR($A35="",C35=""),0,IF(COUNTIF($C$2:C35,C35)=1,SUMIF($C$2:$C$5001,C35,$H$2:$H$5001)+ROW()/10000000,0)) -> 0
H36: =IF($A36="","",IF(OR(NOT(ISNUMBER(E36)),NOT(ISNUMBER(F36))),"",MAX(0,E36)*F36)) | I36: =IF($A36="","",SUMIF($A$2:$A$5001,$A36,$H$2:$H$5001)) | J36: =IF($A36="",0,IF(COUNTIF($A$2:A36,$A36)=1,1,0)) -> 0 | K36: =IF(J36=1,N(I36)+ROW()/10000000,0) -> 0 | L36: =IF(AND(J36=1,N(I36)>0),SUMIF($K$2:$K$5001,">="&K36,$I$2:$I$5001)/MAX(1,SUM($H$2:$H$5001)),"") | M36: =IF($A36="","",INDEX($L$2:$L$5001,MATCH($A36,$A$2:$A$5001,0))) | N36: =IF($A36="","",IF(N(M36)=0,"–",IF(M36<=Start!$D$20,"A",IF(M36<=Start!$D$21,"B","C")))) | O36: =IF($A36="","",IF(NOT(ISNUMBER(F36)),"Wert fehlt; ",IF(F36<=0,"Wert ist 0; ",""))&IF(NOT(ISNUMBER(E36)),"Bestand fehlt; ",IF(E36<0,"Bestand negativ; ",IF(E36=0,"Nullbestand; ","")))&IF(D36="","Warengruppe fehlt; ","")&IF(B36="","Bezeichnung fehlt; ","")&IF(COUNTIFS($A$2:$A$5001,$A36,$C$2:$C$5001,C36)>1,"Artikel doppelt im selben Lager; ","")) | P36: =IF(OR($A36="",D36=""),0,IF(COUNTIF($D$2:D36,D36)=1,SUMIF($D$2:$D$5001,D36,$H$2:$H$5001)+ROW()/10000000,0)) -> 0 | Q36: =IF(OR($A36="",C36=""),0,IF(COUNTIF($C$2:C36,C36)=1,SUMIF($C$2:$C$5001,C36,$H$2:$H$5001)+ROW()/10000000,0)) -> 0
H37: =IF($A37="","",IF(OR(NOT(ISNUMBER(E37)),NOT(ISNUMBER(F37))),"",MAX(0,E37)*F37)) | I37: =IF($A37="","",SUMIF($A$2:$A$5001,$A37,$H$2:$H$5001)) | J37: =IF($A37="",0,IF(COUNTIF($A$2:A37,$A37)=1,1,0)) -> 0 | K37: =IF(J37=1,N(I37)+ROW()/10000000,0) -> 0 | L37: =IF(AND(J37=1,N(I37)>0),SUMIF($K$2:$K$5001,">="&K37,$I$2:$I$5001)/MAX(1,SUM($H$2:$H$5001)),"") | M37: =IF($A37="","",INDEX($L$2:$L$5001,MATCH($A37,$A$2:$A$5001,0))) | N37: =IF($A37="","",IF(N(M37)=0,"–",IF(M37<=Start!$D$20,"A",IF(M37<=Start!$D$21,"B","C")))) | O37: =IF($A37="","",IF(NOT(ISNUMBER(F37)),"Wert fehlt; ",IF(F37<=0,"Wert ist 0; ",""))&IF(NOT(ISNUMBER(E37)),"Bestand fehlt; ",IF(E37<0,"Bestand negativ; ",IF(E37=0,"Nullbestand; ","")))&IF(D37="","Warengruppe fehlt; ","")&IF(B37="","Bezeichnung fehlt; ","")&IF(COUNTIFS($A$2:$A$5001,$A37,$C$2:$C$5001,C37)>1,"Artikel doppelt im selben Lager; ","")) | P37: =IF(OR($A37="",D37=""),0,IF(COUNTIF($D$2:D37,D37)=1,SUMIF($D$2:$D$5001,D37,$H$2:$H$5001)+ROW()/10000000,0)) -> 0 | Q37: =IF(OR($A37="",C37=""),0,IF(COUNTIF($C$2:C37,C37)=1,SUMIF($C$2:$C$5001,C37,$H$2:$H$5001)+ROW()/10000000,0)) -> 0
H38: =IF($A38="","",IF(OR(NOT(ISNUMBER(E38)),NOT(ISNUMBER(F38))),"",MAX(0,E38)*F38)) | I38: =IF($A38="","",SUMIF($A$2:$A$5001,$A38,$H$2:$H$5001)) | J38: =IF($A38="",0,IF(COUNTIF($A$2:A38,$A38)=1,1,0)) -> 0 | K38: =IF(J38=1,N(I38)+ROW()/10000000,0) -> 0 | L38: =IF(AND(J38=1,N(I38)>0),SUMIF($K$2:$K$5001,">="&K38,$I$2:$I$5001)/MAX(1,SUM($H$2:$H$5001)),"") | M38: =IF($A38="","",INDEX($L$2:$L$5001,MATCH($A38,$A$2:$A$5001,0))) | N38: =IF($A38="","",IF(N(M38)=0,"–",IF(M38<=Start!$D$20,"A",IF(M38<=Start!$D$21,"B","C")))) | O38: =IF($A38="","",IF(NOT(ISNUMBER(F38)),"Wert fehlt; ",IF(F38<=0,"Wert ist 0; ",""))&IF(NOT(ISNUMBER(E38)),"Bestand fehlt; ",IF(E38<0,"Bestand negativ; ",IF(E38=0,"Nullbestand; ","")))&IF(D38="","Warengruppe fehlt; ","")&IF(B38="","Bezeichnung fehlt; ","")&IF(COUNTIFS($A$2:$A$5001,$A38,$C$2:$C$5001,C38)>1,"Artikel doppelt im selben Lager; ","")) | P38: =IF(OR($A38="",D38=""),0,IF(COUNTIF($D$2:D38,D38)=1,SUMIF($D$2:$D$5001,D38,$H$2:$H$5001)+ROW()/10000000,0)) -> 0 | Q38: =IF(OR($A38="",C38=""),0,IF(COUNTIF($C$2:C38,C38)=1,SUMIF($C$2:$C$5001,C38,$H$2:$H$5001)+ROW()/10000000,0)) -> 0
H39: =IF($A39="","",IF(OR(NOT(ISNUMBER(E39)),NOT(ISNUMBER(F39))),"",MAX(0,E39)*F39)) | I39: =IF($A39="","",SUMIF($A$2:$A$5001,$A39,$H$2:$H$5001)) | J39: =IF($A39="",0,IF(COUNTIF($A$2:A39,$A39)=1,1,0)) -> 0 | K39: =IF(J39=1,N(I39)+ROW()/10000000,0) -> 0 | L39: =IF(AND(J39=1,N(I39)>0),SUMIF($K$2:$K$5001,">="&K39,$I$2:$I$5001)/MAX(1,SUM($H$2:$H$5001)),"") | M39: =IF($A39="","",INDEX($L$2:$L$5001,MATCH($A39,$A$2:$A$5001,0))) | N39: =IF($A39="","",IF(N(M39)=0,"–",IF(M39<=Start!$D$20,"A",IF(M39<=Start!$D$21,"B","C")))) | O39: =IF($A39="","",IF(NOT(ISNUMBER(F39)),"Wert fehlt; ",IF(F39<=0,"Wert ist 0; ",""))&IF(NOT(ISNUMBER(E39)),"Bestand fehlt; ",IF(E39<0,"Bestand negativ; ",IF(E39=0,"Nullbestand; ","")))&IF(D39="","Warengruppe fehlt; ","")&IF(B39="","Bezeichnung fehlt; ","")&IF(COUNTIFS($A$2:$A$5001,$A39,$C$2:$C$5001,C39)>1,"Artikel doppelt im selben Lager; ","")) | P39: =IF(OR($A39="",D39=""),0,IF(COUNTIF($D$2:D39,D39)=1,SUMIF($D$2:$D$5001,D39,$H$2:$H$5001)+ROW()/10000000,0)) -> 0 | Q39: =IF(OR($A39="",C39=""),0,IF(COUNTIF($C$2:C39,C39)=1,SUMIF($C$2:$C$5001,C39,$H$2:$H$5001)+ROW()/10000000,0)) -> 0
H40: =IF($A40="","",IF(OR(NOT(ISNUMBER(E40)),NOT(ISNUMBER(F40))),"",MAX(0,E40)*F40)) | I40: =IF($A40="","",SUMIF($A$2:$A$5001,$A40,$H$2:$H$5001)) | J40: =IF($A40="",0,IF(COUNTIF($A$2:A40,$A40)=1,1,0)) -> 0 | K40: =IF(J40=1,N(I40)+ROW()/10000000,0) -> 0 | L40: =IF(AND(J40=1,N(I40)>0),SUMIF($K$2:$K$5001,">="&K40,$I$2:$I$5001)/MAX(1,SUM($H$2:$H$5001)),"") | M40: =IF($A40="","",INDEX($L$2:$L$5001,MATCH($A40,$A$2:$A$5001,0))) | N40: =IF($A40="","",IF(N(M40)=0,"–",IF(M40<=Start!$D$20,"A",IF(M40<=Start!$D$21,"B","C")))) | O40: =IF($A40="","",IF(NOT(ISNUMBER(F40)),"Wert fehlt; ",IF(F40<=0,"Wert ist 0; ",""))&IF(NOT(ISNUMBER(E40)),"Bestand fehlt; ",IF(E40<0,"Bestand negativ; ",IF(E40=0,"Nullbestand; ","")))&IF(D40="","Warengruppe fehlt; ","")&IF(B40="","Bezeichnung fehlt; ","")&IF(COUNTIFS($A$2:$A$5001,$A40,$C$2:$C$5001,C40)>1,"Artikel doppelt im selben Lager; ","")) | P40: =IF(OR($A40="",D40=""),0,IF(COUNTIF($D$2:D40,D40)=1,SUMIF($D$2:$D$5001,D40,$H$2:$H$5001)+ROW()/10000000,0)) -> 0 | Q40: =IF(OR($A40="",C40=""),0,IF(COUNTIF($C$2:C40,C40)=1,SUMIF($C$2:$C$5001,C40,$H$2:$H$5001)+ROW()/10000000,0)) -> 0
